Workbook

Sheet Raw data
B2: 성별 | C2: 성함 | D2: 연락처 | E2: 직업(직장과 파트) | F2: 나이 | G2: 상대 - 선호 나이대 (중복가능) | H2: 키 | I2: 상대 - 이상형 키 (중복가능) | J2: MBTI | K2: 상대 - 원하는 MBTI | L2: 종교 | M2: 상대 - 선호종교 | N2: 나는 어떤사람? | O2: 이상형 | P2: 상대 - 비선호 직군 (중복가능) | Q2: 운영진에게 건의사항 or 요청사항 (필수X)
A3: 1 | B3: 남 | C3: 강기태 | D3: 010-2307-9728 | E3: 작업치료사 | F3: 34 | G3: 28~34 | H3: 178 | I3: 무관 | J3: ENFP | K3: INFP, INFJ, INTJ, ISFJ, ENFP, ESFP, ENFJ, ESFJ, ENTP, ENTJ | L3: 무교 | M3: 동일 | N3: 긍정적이고 밝은사람 | O3: 밝고 재밌는분 | P3: 무관 | R3: 동의
A4: 2 | B4: 여 | C4: 강다영 | D4: 1047890745 | E4: 헤어디자이너 | F4: 31 | G4: 28~38 | H4: 169 | I4: 180~ | J4: ESTP | K4: 무관 | L4: 무교 | M4: 동일 | N4: 밝고 뒤끝없는사람 | O4: 헬스하고 하얀사람..? 어른스럽고 차분한사람 | P4: 무관 | R4: 동의
A5: 3 | B5: 남 | C5: 강병규 | D5: 1052521809 | E5: 디스플레이허브 기술파트 | F5: 27 | G5: 20~27 | H5: 172 | I5: ~165 | J5: ENTJ | K5: 무관 | L5: 기독교 | M5: 동일, 무관 | N5: 항상 긍정적으로 살아가려고 노력하고 굴곡이 맞지 않은 사람 | O5: 베이지가 잘 어울리는 여자 | P5: 무관 | R5: 동의
A6: 4 | B6: 여 | C6: 강영연 | D6: 1098258435 | E6: 회사원 | F6: 45 | G6: 42~ | H6: 170 | I6: 175~ | J6: ISFJ | K6: 무관 | L6: 천주교 | M6: 무관 | N6: 다정하고 재밌는 사람 | O6: 다정하고 세심한 사람 | P6: 무관 | R6: 동의
A7: 5 | B7: 여 | C7: 강유진 | D7: 1082105352 | E7: 포워딩회사 | F7: 31 | G7: 31~38 | H7: 158 | I7: 170~ | J7: ISFJ | K7: ENFP, ESFP, ENFJ, ESFJ, ENTP, ESTP, ENTJ | L7: 무교 | M7: 무관 | N7: 겉모습은 차가워보일 수 있지만 알고보면 털털하고 웃음이 많은 사람 | O7: 다정하고 긍정적인사람 | P7: 무관 | R7: 동의
A8: 6 | B8: 여 | C8: 강이경 | D8: 010-6812-2569 | E8: 필라테스강사 | F8: 31 | G8: 28~34 | H8: 170 | I8: 170~ | J8: ESTJ | K8: INFP, ISFP, INTP, ISTP, INFJ, ISFJ, ENFJ, ESFJ | L8: 무교 | M8: 동일 | N8: 몸과 마음이 건강한 사람! | O8: 운동하고 밝은분 | P8: 무관 | Q8: 비흡연자 원해요 | R8: 동의
A9: 7 | B9: 여 | C9: 강현지 | D9: 1024145998 | E9: 전임교수(대구 4년제 사립대학교, 간호학과) | F9: 34 | G9: 31~41 | H9: 160 | I9: 170~ | J9: ESFJ | K9: 무관 | L9: 무교, 불교 | M9: 동일 | N9: 학문 쪽 커리어를 쌓아온 사람이라 삶의 방향이 뚜렷하고, 관계에서는 관계에서는 상대를 먼저 살피는 사람이라서 안정감을 주는 편 | O9: 여유있고 상황을 회피하지 않는 사람, 직업적/경제적으로 안정된 상태 | P9: 공무원, 연구직, 회사원 | Q9: 서울-대구 장거리연애&주말부부 상관없는 분이 좋습니다. | R9: 동의
A10: 8 | B10: 여 | C10: 강혜진 | D10: 1031303829 | E10: 서비스직(아티제, 바리스타) | F10: 34 | G10: 31~38 | H10: 15 | I10: 175~180 | J10: INFJ | K10: 무관 | L10: 불교 | M10: 무관 | N10: 밝고 다른 사람들과 즐겁게 지내는 걸 좋아하는 사람 | O10: 대화가 통하고 가정적인 사람 | P10: 연구직 | R10: 동의
A11: 9 | B11: 여 | C11: 공윤재 | D11: 1072918842 | E11: 공인중개사 대표 | F11: 32 | G11: 28~34 | H11: 171 | I11: 175~ | J11: ENFJ ESFJ | K11: 무관 | L11: 무교 | M11: 동일 | N11: 밝고 다정한편이고 직진스타일 입니다! 운동이랑 관리도 꾸준히 하고 성실하게 살아가려고 하고 있어요! | O11: 키 크고 즐겨하시는 운동이 있으셨으면 좋겠습니다! | P11: 자영업, 공무원 | R11: 동의
A12: 10 | B12: 남 | C12: 곽원호 | D12: 1037786910 | E12: 제조업 | F12: 49 | G12: 35~ | H12: 175 | I12: ~165 | J12: INFJ | K12: 무관 | L12: 무교 | M12: 무관 | N12: 낮을 좀 가리지만 친해지면 말많고 이야기 잘하지만 나서는 스타일이 아님 소극적이지만 적극적일때는 또 달라짐 | O12: 밝고 웃는 사람 제가 조용하고 그러다보니 좀 저는 밝고 웃는 사람 이었으면 좋겠습니다 | P12: 무관 | Q12: 잘 부탁 드립니다 | R12: 동의
A13: 11 | B13: 여 | C13: 곽찬미 | D13: 1050546323 | E13: 회사원(출판업계) | F13: 37 | G13: 무관 | H13: 158 | I13: 175~ | J13: ENFJ | K13: 무관 | L13: 무교 | M13: 무관 | N13: 투명한 사람 | O13: 대화코드 잘 맞는 분, 선하신 분 | P13: 무관 | R13: 동의
A14: 13 | B14: 남 | C14: 권민재 | D14: 1085686931 | E14: 자영업자 (통신업, 법인 임원/개인사업자 대표) | F14: 34 | G14: 28~34 | H14: 168 | I14: ~160 | J14: ENTJ | K14: 무관 | L14: 무교 | M14: 무관 | N14: 진취적, 성장과 성공을 목표로 하는 사람 | O14: 외적, 작고 아담한 스타일 (연예인, 박보영 남보라 윈터) 내적, 든든한 동료로서 미래를 함께 그려나갈 수 있는 분 | P14: 무관 | Q14: 베이킹을 통해 인연을 만나는 자리가 있다는걸 처음 알았네요, 좋은 자리 만들어주셔서 감사합니다. 좋은 인연 만날 수 있기를 기원합니다🙏 | R14: 동의
A15: 14 | B15: 남 | C15: 권영훈 | D15: 010-5566-4480 | E15: 코웰메디 임플란트 / 영업센터장 | F15: 43 | G15: 35~41 | H15: 175 | I15: ~170 | J15: ISTP | K15: ISFP, ISTP, ISTJ, ESFP, ESFJ, ESTP, ESTJ | L15: 무교 | M15: 무관 | N15: 차분하고 상대의 이야기를 잘 들어주고 배려심 있는 감정의 기복이 크지 않아요. | O15: 잘 웃고 배려심 있으며 자신만의 독특한 매력이 있는 사람 | P15: 병원직군 | Q15: 업무로 인해 참석이 어려운 날에 배정된다면 변경이 가능한지 궁금합니다 | R15: 동의
A16: 15 | B16: 여 | C16: 김가영 | D16: 1022558313 | E16: 소품샵 매니저 | F16: 35 | G16: 31~38 | H16: 152 | I16: 170~180 | J16: ISTP | K16: 무관 | L16: 무교 | M16: 동일, 무관 | N16: 매너가 좋은 사람 | O16: 차태현 최우식 | P16: 무관 | Q16: 안녕하세요! 제가 직업 특성상 월, 화요일에 쉬어서 이때만 가능합니다 | R16: 동의
A17: 16 | B17: 여 | C17: 김가현 | D17: 1024650470 | E17: 간호사 | F17: 29 | G17: 24~31 | H17: 160 | I17: 170~180 | J17: INFP | K17: 무관 | L17: 무교 | M17: 동일 | N17: 잘 웃고 상대방을 배려하는 사람 | O17: 귀엽고 다정다감한 사람 + 비흡연자 | P17: 무관 | R17: 동의
A18: 17 | B18: 여 | C18: 김경선 | D18: 1073380874 | E18: 시립어린이집교사-주임교사 | F18: 41 | G18: 38~41 | H18: 164 | I18: 175~180 | J18: ISFP-ISTJ | K18: 무관 | L18: 무교 | M18: 무관 | N18: 164에 58-9 통통한 편이고, 참해보인다는 이야기를 종종듣는 인상입노다. 친해지면 털털하고 애교도 있는데, 낮가림이 있어 먼저 다가가 편해지는데 시간을 필요로 합니다. 올곧게 바르게 살았고, 앞으로도 그럴 예정입니다. 여행을 좋아하고 맛있는걸 좋아합니다^^ | O18: 너무 감수성이 높은 사람은 잘 안맞는것 같아요.유쾌하고 투명한 사람이 좋습니다. 성실한 사람이 좋습니다.노담이면 좋지만 아니어도 상관없고, 문신은 어려울것같습니다. | P18: 자영업 | R18: 동의
A19: 18 | B19: 여 | C19: 김경희 | D19: 1047334785 | E19: 부산대학병원 간호부 | F19: 38 | G19: 35~41 | H19: 161 | I19: 170~ | J19: ESFJ | K19: 무관 | L19: 무교 | M19: 동일 | N19: 차분함, 다정함, 꾸준함, 혼자서도 시간 잘 보냄 | O19: 다정, 안정적인분 | P19: 자영업 | R19: 동의
A20: 19 | B20: 남 | C20: 김광민 | D20: 1077660615 | E20: 회사원(플랫폼업체 영업직) | F20: 28 | G20: 28~31 | H20: 181 | I20: 160~170 | J20: ISFJ | K20: 무관 | L20: 무교 | M20: 무관 | N20: 상대방에게 웃음을 주는 게 좋고 일상 대화를 하면서 평일에 받았던 스트레스가 풀리기도 합니다 처음에는 어색해하기도 하고 낯도 많이 가리기도 하지만 몇 번 얘기하다 보면 어색함도 풀리고 더 말을 걸고 있기도 합니다 일과 생활이 완벽하게 분리가 되어있어 일할 때는 일만 하고 쉴 때는 절대 일 생각도 안 하고 일 얘기도 안 하고 살아가고 있습니다 취미는 야구를 보러 다니고 주말 아침에 축구를 하러 나가고 있습니다 야구를 같이 보러 다니는 걸 좋아하며 맛있는 음식점이 생각나면 찾아가는것도 좋아합니다 집 데이트와 밖에서 하는 데이트를 한쪽으로 몰리지 않게 하는 걸 좋아합니다 연애 스타일은 주도적인 편은 아닌 거 같고 상대방에게 맞춰주는 편입니다 뭘 하든 대화를 통해 하려고 하며 싸우더라도 대화로 바로 푸는 스타일이며 한번 좋아하기 시작하면 정말 정말 많이 좋아하는 타입입니다 | O20: 안정적이며 대화가 잘 통하는 사람 연상이면 더 좋을거같고 연하는 선호하지 않습니다 | P20: 무관 | R20: 동의
A21: 20 | B21: 여 | C21: 김나영 | D21: 1036959322 | E21: (직장)어린이집 교사 | F21: 26 | G21: 20~31 | H21: 161 | I21: 170~ | J21: ISFJ | K21: ISFP, ISTP, INFJ, ISTJ, INTJ, ISFJ, ESFP, ENFJ, ESFJ, ENTP, ESTP, ENTJ, ESTJ | L21: 기독교 | M21: 동일, 무관 | N21: 처음 볼 때 낯가림이 있어 조금 뚝닥대고 차가워보일 수 있으나 사람 좋아하고 정이 많음. 집순이, 남사친 X 외적으로 통통한 편.. 빵 좋아하고 작고 귀여운 것들 좋아함. 최애 캐릭터는 짱구,, 입니다. | O21: 담배, 문신 X / 키 175 이상에 직업 있고 자기 일 열심히 하는 사람. 안경은 약간 비선호.. 무쌍이나 얇은 유쌍 선호(아랍 보다는 두부 선호) 마른 체형보다는 조금 덩치가 있는 분 선호(근육질X) | P21: 무관 | R21: 동의
A22: 21 | B22: 여 | C22: 김다슬 | D22: 1051089080 | E22: 신라스테이 경영지원 | F22: 29 | G22: 31~34 | H22: 164 | I22: 175~ | J22: ESTJ/ ESTP | K22: 무관, INFP, ISFP, INFJ, ISFJ, ENFP, ESFP, ENFJ, ESFJ | L22: 무교 | M22: 동일, 무관 | N22: 외관상 도도해보여 다가가기 어려워보이나 내면은 순딩순딩 친해지면 첫인상과 전혀 다른 마음 따뜻한 사람 | O22: 키큰 강아지상 | P22: 병원직군, 공무원 | R22: 동의
A23: 22 | B23: 남 | C23: 김동국 | D23: 1091113105 | E23: 대학병원 행정직 | F23: 37 | G23: 28~38 | H23: 174 | I23: 160~170 | J23: ISTP | K23: 무관 | L23: 천주교 | M23: 무관 | N23: 다정하고 잘 챙겨주는사람 | O23: 청순하고 털털하신분 | P23: 무관 | R23: 동의
A24: 23 | B24: 남 | C24: 김문환 | D24: 1085750129 | E24: 작가, 철학연구가 | F24: 40 | G24: 31~41 | H24: 176 | I24: 160~170 | J24: ENTP | K24: 무관 | L24: 무교 | M24: 무관 | N24: 장난기 많지만 진중한 사람 | P24: 무관 | R24: 동의
A25: 24 | B25: 여 | C25: 김민경 | D25: 1094131786 | E25: 대기업계열사, 사이버 보안 | F25: 32 | G25: 31~34 | H25: 171 | I25: 175~180 | J25: ENFP | K25: 무관 | L25: 불교 | M25: 무관 | N25: 잘웃고 리액션 장인이라는 소리를 많이 들어요 | O25: 제 키를 부담스러워하지 않는 사람, 말을 예쁘게 하는 사람 | P25: 자영업 | R25: 동의
A26: 25 | B26: 여 | C26: 김민영 | D26: 1085700389 | E26: 디자이너 | F26: 35 | G26: 31~38 | H26: 156 | I26: 170~180 | J26: INFJ | K26: 무관 | L26: 천주교 | M26: 동일, 무관 | N26: 밝고 긍정적이고 유쾌한사람 | O26: 운동하는 사람! | P26: 무관 | R26: 동의
A27: 26 | B27: 여 | C27: 김민정 | D27: 1058380435 | E27: 어린이집/보육교사 | F27: 30 | G27: 28~34 | H27: 155 | I27: 170~180 | J27: ISTJ | K27: 무관 | L27: 무교 | M27: 동일 | N27: 안녕하세요. 아이들을 가르치는 일을 하고 있고, 성실하게 하루하루 보내려고 노력하는 편입니다. 아침 수영으로 하루를 시작하는 걸 좋아합니다. 대화가 편하고 서로 배려할 수 있는 분을 만나면 좋겠습니다. | O27: 다정한사람 | P27: 자영업 | R27: 동의
A28: 27 | B28: 여 | C28: 김민정 | D28: 1064833091 | E28: 자영업자(애견미용사 | F28: 32 | G28: 28~34 | H28: 172 | I28: 180~ | J28: INFJ | K28: 무관 | L28: 무교 | M28: 무관 | N28: 다정한사람 | O28: 키크고 자기관리 잘하고 운동 잘하는 사람 | P28: 자영업, 무관 | R28: 동의
A29: 28 | B29: 여 | C29: 김민정 | D29: 1046643991 | E29: 유치원교사 | F29: 39 | G29: 35~41 | H29: 153 | I29: 170~180 | J29: ESFJ | K29: 무관 | L29: 무교 | M29: 동일 | N29: 긍정적이고 활동적인 사람 | O29: 대화가 잘되는 사람 | P29: 자영업 | R29: 동의
A30: 29 | B30: 남 | C30: 김민호 | D30: 1049764250 | E30: 회사원 (유통업) | F30: 31 | G30: 24~31 | H30: 171 | I30: 160~165 | J30: ISFP | K30: ISFP, ENFP, ESFP, ENFJ, ESFJ | L30: 무교 | M30: 동일 | N30: 친해지기 전까진 조용한 꼼꼼한 에겐 친해지면 댕댕미 있는 | O30: 고양이상 꼼꼼하고 돌려말하지않는 여자..? | P30: 무관 | R30: 동의
A31: 30 | B31: 여 | C31: 김민희 | D31: 1041154565 | E31: 전산직 | F31: 31 | G31: 28~31 | H31: 175 | I31: 180~ | J31: ESFJ | K31: INFJ, ISTJ, INTJ, ISFJ, ENFJ, ESFJ, ESTJ | N31: 매력적이고 다정한 사람. 타인을 이해하고 배려할 줄 안다. | O31: 키크고 마르지 않은 체형. 배려심 있고 책임감 있는 사람 | P31: 병원직군, 기술직, 공무원, 연구직, 회사원 | Q31: 키 큰 사람을 원해요,, | R31: 동의
A32: 31 | B32: 남 | C32: 김반석 | D32: 1055033404 | E32: IT엔지니어 | F32: 31 | G32: 28~31 | H32: 176 | I32: 160~170 | J32: ISFP | K32: 무관 | L32: 기독교 | M32: 무관 | N32: 저는 솔직한 편이라, 좋고 싫은 게 표정에 조금 드러나는 편이에요. 그래서 오히려 편하다는 얘기를 듣기도 해요. 인연을 소중하게 생각하는 편이라 한 번 만나면 오래 보고 싶은 스타일이고요. 너무 무겁기보다는, 가끔씩 툭툭 웃기는 편이에요. 목표가 생기면 어떻게든 이루려고 노력하는 편이라, 스스로는 진취적인 성향이라고 생각합니다. 잘 부탁드립니다 🙂 | O32: 비흡연자였으면 좋겠고, 긴 머리가 잘 어울리는 분을 좋아해요. 연하이신 분이 조금 더 편하게 느껴지고, 같이 있을 때 밝고 에너지가 좋은 분이면 더 잘 맞을 것 같아요. | P32: 무관 | R32: 동의
A33: 32 | B33: 남 | C33: 김사윤 | D33: 010-9870-8563 | E33: 개인 광고사진 스튜디오 | F33: 38 | G33: 28~38 | H33: 168 | I33: ~165 | J33: INTJ | K33: INFP, ISFP, INFJ, ENFP, ESFP, ENFJ, ENTJ | L33: 무교, 천주교, 불교 | M33: 동일 | N33: 서울에서 광고사진 스튜디오를 운영하는 전문사진가입니다. | P33: 병원직군, 기술직, 자영업, 공무원, 회사원, 무관 | R33: 동의
A34: 33 | B34: 여 | C34: 김상아 | D34: 1041574806 | E34: 필라테스 협회 교육강사 | F34: 30 | G34: 31~38 | H34: 158 | I34: 175~ | J34: ESFP | K34: INFP, ISFP, INFJ, INTJ, ISFJ, ENFJ, ESFJ, ENTJ, ESTJ | L34: 기독교 | M34: 무관 | N34: 분위기가 밝고 따뜻한사람 | O34: 회피형 아니고 대화 잘되는 분, 안정적인 사람 | P34: 무관 | R34: 동의
A35: 34 | B35: 여 | C35: 김성연 | D35: 1032462090 | E35: 광고대행사 마케팅 | F35: 27 | G35: 28~34 | H35: 169 | I35: 170~ | J35: ESFP | K35: 무관 | L35: 무교 | M35: 무관 | N35: 챙겨주고 챙김받는 거 좋아하는 사람 온전히 집중할 줄 아는사람 밝고 활동적인사람 | O35: 술 많이 좋아하지않고 거짓말하지않는 사람 자기일 잘 하고있고 자격지심없는사람 | P35: 무관 | R35: 동의
A36: 35 | B36: 남 | C36: 김성윤 | D36: 1073391290 | E36: 인지컨트롤스 배터리설계팀 | F36: 28 | G36: 24~31 | H36: 180 | I36: 160~175 | J36: INFP | K36: 무관 | L36: 무교 | M36: 동일 | N36: 항상 긍정적이며 밝은 이미지를 가졌고 친구들이 부르는 별명으로는 골든리트리버라는 별명을 가졌습니다 애교도 많고 잘 놀아요! | O36: 정직하고 순하면서 바람 안피고 감정에 높낮이가 없는 사람이요 | P36: 자영업 | R36: 동의
A37: 36 | B37: 여 | C37: 김세련 | D37: 1088248684 | E37: 경찰 공무원 | F37: 38 | G37: 35~41 | H37: 167 | I37: 175~ | J37: ISFJ | K37: 무관 | L37: 무교 | M37: 무관 | N37: 책임감이 강하고 성실하고 사랑하는 사람을 챙겨주고 지지해줄수 있는 지혜로운 사람! | O37: 사람을 소중하게 생각하고 다름을 인정하고 마음이 따뜻한 사람 | P37: 무관 | R37: 동의
A38: 37 | B38: 여 | C38: 김세아 | D38: 1071281563 | E38: 삼화 -HR팀 | F38: 38 | G38: 35~41 | H38: 170 | I38: 175~ | J38: ENTP | K38: 무관, ENFP, ENFJ | L38: 무교 | M38: 동일 | N38: 세련된 취향과 따뜻한 정을 동시에 가진, '알수록 무해하고 매력적인' 사람입니다. 평일엔 치열하게 일하고, 주말엔 드라이브와 운동으로 에너지를 채우는 갓생러(God-生)예요." | O38: "함께 있으면 친구처럼 편안하고 티격태격 수다 떨 수 있는 분이 이상형이에요. 본인 일에 열정적이면서도 퇴근 후엔 드라이브 한 잔의 여유를 즐길 줄 아는 듬직한 체격의 남자다운 분이면 좋겠습니다. 무엇보다 대화가 잘 통하고 배울 점이 있는 분에게 매력을 느낍니다. | P38: 무관 | R38: 동의
A39: 38 | B39: 여 | C39: 김세정 | D39: 1063877374 | E39: 행사기획자(국제회의) | F39: 27 | G39: 28~34 | H39: 160 | I39: 175~180 | J39: ISFJ | K39: INFJ, ENFP, ESFJ | L39: 무교 | M39: 동일 | N39: 차분하지만 밝은 사람 | O39: 유머코드, 대화가 잘 통하는 사람, 외모(두부상) | P39: 무관 | R39: 동의
A40: 39 | B40: 여 | C40: 김세향 | D40: 1062305288 | E40: 엔터테인먼트/매니저 | F40: 31 | G40: 31~38 | H40: 164 | I40: 175~ | J40: ESFJ/ESTJ | K40: 무관 | L40: 무교, 불교 | M40: 동일 | N40: 알아갈 수록 첫인상이랑 다른 사람 | O40: 골격이 크고 다정하고 상대가 뭘 좋아할까 고민하는 사람 | P40: 자영업 | R40: 동의
A41: 40 | B41: 여 | C41: 김송미 | D41: 1021089193 | E41: 소니/scm | F41: 35 | G41: 31~38 | H41: 166 | I41: 175~ | J41: ENFJ | K41: INFJ, ISTJ, INTJ, ISFJ, ENFJ, ESFJ, ENTJ, ESTJ | L41: 무교 | M41: 무관 | N41: 밝고 긍정적인사람 | O41: 자기 관리 열심히하고 배울점이 있는사람 | P41: 자영업 | R41: 동의
...

Sheet 자료정리
B2: 성별 | C2: 이름 | D2: 나이 | E2: 키 | F2: 직업(직장과 파트) | G2: 선호나이 | H2: 선호 키 | I2: MBTI | J2: 선호 MBTI | K2: 종교 | L2: 상대 - 선호종교 | M2: 비선호 직군 | N2: 간단한 자기소개 | O2: 이상형 | P2: 건의사항
A3: 1 | B3: ='Raw data'!B3 -> 남 | C3: ='Raw data'!C3 -> 강기태 | D3: ='Raw data'!F3 -> 34 | E3: ='Raw data'!H3 -> 178 | F3: ='Raw data'!E3 -> 작업치료사 | G3: ='Raw data'!G3 -> 28~34 | H3: ='Raw data'!I3 -> 무관 | I3: ='Raw data'!J3 -> ENFP | J3: ='Raw data'!K3 -> INFP, INFJ, INTJ, ISFJ, ENFP, ESFP, ENFJ, ESFJ, ENTP, ENTJ | K3: ='Raw data'!L3 -> 무교 | L3: ='Raw data'!M3 -> 동일 | M3: ='Raw data'!P3 -> 무관 | N3: ='Raw data'!N3 -> 긍정적이고 밝은사람 | O3: ='Raw data'!O3 -> 밝고 재밌는분 | P3: ='Raw data'!Q3 -> 0
A4: 2 | B4: ='Raw data'!B4 -> 여 | C4: ='Raw data'!C4 -> 강다영 | D4: ='Raw data'!F4 -> 31 | E4: ='Raw data'!H4 -> 169 | F4: ='Raw data'!E4 -> 헤어디자이너 | G4: ='Raw data'!G4 -> 28~38 | H4: ='Raw data'!I4 -> 180~ | I4: ='Raw data'!J4 -> ESTP | J4: ='Raw data'!K4 -> 무관 | K4: ='Raw data'!L4 -> 무교 | L4: ='Raw data'!M4 -> 동일 | M4: ='Raw data'!P4 -> 무관 | N4: ='Raw data'!N4 -> 밝고 뒤끝없는사람 | O4: ='Raw data'!O4 -> 헬스하고 하얀사람..? 어른스럽고 차분한사람 | P4: ='Raw data'!Q4 -> 0
A5: 3 | B5: ='Raw data'!B5 -> 남 | C5: ='Raw data'!C5 -> 강병규 | D5: ='Raw data'!F5 -> 27 | E5: ='Raw data'!H5 -> 172 | F5: ='Raw data'!E5 -> 디스플레이허브 기술파트 | G5: ='Raw data'!G5 -> 20~27 | H5: ='Raw data'!I5 -> ~165 | I5: ='Raw data'!J5 -> ENTJ | J5: ='Raw data'!K5 -> 무관 | K5: ='Raw data'!L5 -> 기독교 | L5: ='Raw data'!M5 -> 동일, 무관 | M5: ='Raw data'!P5 -> 무관 | N5: ='Raw data'!N5 -> 항상 긍정적으로 살아가려고 노력하고 굴곡이 맞지 않은 사람 | O5: ='Raw data'!O5 -> 베이지가 잘 어울리는 여자 | P5: ='Raw data'!Q5 -> 0
A6: 4 | B6: ='Raw data'!B6 -> 여 | C6: ='Raw data'!C6 -> 강영연 | D6: ='Raw data'!F6 -> 45 | E6: ='Raw data'!H6 -> 170 | F6: ='Raw data'!E6 -> 회사원 | G6: ='Raw data'!G6 -> 42~ | H6: ='Raw data'!I6 -> 175~ | I6: ='Raw data'!J6 -> ISFJ | J6: ='Raw data'!K6 -> 무관 | K6: ='Raw data'!L6 -> 천주교 | L6: ='Raw data'!M6 -> 무관 | M6: ='Raw data'!P6 -> 무관 | N6: ='Raw data'!N6 -> 다정하고 재밌는 사람 | O6: ='Raw data'!O6 -> 다정하고 세심한 사람 | P6: ='Raw data'!Q6 -> 0
A7: 5 | B7: ='Raw data'!B7 -> 여 | C7: ='Raw data'!C7 -> 강유진 | D7: ='Raw data'!F7 -> 31 | E7: ='Raw data'!H7 -> 158 | F7: ='Raw data'!E7 -> 포워딩회사 | G7: ='Raw data'!G7 -> 31~38 | H7: ='Raw data'!I7 -> 170~ | I7: ='Raw data'!J7 -> ISFJ | J7: ='Raw data'!K7 -> ENFP, ESFP, ENFJ, ESFJ, ENTP, ESTP, ENTJ | K7: ='Raw data'!L7 -> 무교 | L7: ='Raw data'!M7 -> 무관 | M7: ='Raw data'!P7 -> 무관 | N7: ='Raw data'!N7 -> 겉모습은 차가워보일 수 있지만 알고보면 털털하고 웃음이 많은 사람 | O7: ='Raw data'!O7 -> 다정하고 긍정적인사람 | P7: ='Raw data'!Q7 -> 0
A8: 6 | B8: ='Raw data'!B8 -> 여 | C8: ='Raw data'!C8 -> 강이경 | D8: ='Raw data'!F8 -> 31 | E8: ='Raw data'!H8 -> 170 | F8: ='Raw data'!E8 -> 필라테스강사 | G8: ='Raw data'!G8 -> 28~34 | H8: ='Raw data'!I8 -> 170~ | I8: ='Raw data'!J8 -> ESTJ | J8: ='Raw data'!K8 -> INFP, ISFP, INTP, ISTP, INFJ, ISFJ, ENFJ, ESFJ | K8: ='Raw data'!L8 -> 무교 | L8: ='Raw data'!M8 -> 동일 | M8: ='Raw data'!P8 -> 무관 | N8: ='Raw data'!N8 -> 몸과 마음이 건강한 사람! | O8: ='Raw data'!O8 -> 운동하고 밝은분 | P8: ='Raw data'!Q8 -> 비흡연자 원해요
A9: 7 | B9: ='Raw data'!B9 -> 여 | C9: ='Raw data'!C9 -> 강현지 | D9: ='Raw data'!F9 -> 34 | E9: ='Raw data'!H9 -> 160 | F9: ='Raw data'!E9 -> 전임교수(대구 4년제 사립대학교, 간호학과) | G9: ='Raw data'!G9 -> 31~41 | H9: ='Raw data'!I9 -> 170~ | I9: ='Raw data'!J9 -> ESFJ | J9: ='Raw data'!K9 -> 무관 | K9: ='Raw data'!L9 -> 무교, 불교 | L9: ='Raw data'!M9 -> 동일 | M9: ='Raw data'!P9 -> 공무원, 연구직, 회사원 | N9: ='Raw data'!N9 -> 학문 쪽 커리어를 쌓아온 사람이라 삶의 방향이 뚜렷하고, 관계에서는 관계에서는 상대를 먼저 살피는 사람이라서 안정감을 주는 편 | O9: ='Raw data'!O9 -> 여유있고 상황을 회피하지 않는 사람, 직업적/경제적으로 안정된 상태 | P9: ='Raw data'!Q9 -> 서울-대구 장거리연애&주말부부 상관없는 분이 좋습니다.
A10: 8 | B10: ='Raw data'!B10 -> 여 | C10: ='Raw data'!C10 -> 강혜진 | D10: ='Raw data'!F10 -> 34 | E10: ='Raw data'!H10 -> 15 | F10: ='Raw data'!E10 -> 서비스직(아티제, 바리스타) | G10: ='Raw data'!G10 -> 31~38 | H10: ='Raw data'!I10 -> 175~180 | I10: ='Raw data'!J10 -> INFJ | J10: ='Raw data'!K10 -> 무관 | K10: ='Raw data'!L10 -> 불교 | L10: ='Raw data'!M10 -> 무관 | M10: ='Raw data'!P10 -> 연구직 | N10: ='Raw data'!N10 -> 밝고 다른 사람들과 즐겁게 지내는 걸 좋아하는 사람 | O10: ='Raw data'!O10 -> 대화가 통하고 가정적인 사람 | P10: ='Raw data'!Q10 -> 0
A11: 9 | B11: ='Raw data'!B11 -> 여 | C11: ='Raw data'!C11 -> 공윤재 | D11: ='Raw data'!F11 -> 32 | E11: ='Raw data'!H11 -> 171 | F11: ='Raw data'!E11 -> 공인중개사 대표 | G11: ='Raw data'!G11 -> 28~34 | H11: ='Raw data'!I11 -> 175~ | I11: ='Raw data'!J11 -> ENFJ ESFJ | J11: ='Raw data'!K11 -> 무관 | K11: ='Raw data'!L11 -> 무교 | L11: ='Raw data'!M11 -> 동일 | M11: ='Raw data'!P11 -> 자영업, 공무원 | N11: ='Raw data'!N11 -> 밝고 다정한편이고 직진스타일 입니다! 운동이랑 관리도 꾸준히 하고 성실하게 살아가려고 하고 있어요! | O11: ='Raw data'!O11 -> 키 크고 즐겨하시는 운동이 있으셨으면 좋겠습니다! | P11: ='Raw data'!Q11 -> 0
A12: 10 | B12: ='Raw data'!B12 -> 남 | C12: ='Raw data'!C12 -> 곽원호 | D12: ='Raw data'!F12 -> 49 | E12: ='Raw data'!H12 -> 175 | F12: ='Raw data'!E12 -> 제조업 | G12: ='Raw data'!G12 -> 35~ | H12: ='Raw data'!I12 -> ~165 | I12: ='Raw data'!J12 -> INFJ | J12: ='Raw data'!K12 -> 무관 | K12: ='Raw data'!L12 -> 무교 | L12: ='Raw data'!M12 -> 무관 | M12: ='Raw data'!P12 -> 무관 | N12: ='Raw data'!N12 -> 낮을 좀 가리지만 친해지면 말많고 이야기 잘하지만 나서는 스타일이 아님 소극적이지만 적극적일때는 또 달라짐 | O12: ='Raw data'!O12 -> 밝고 웃는 사람 제가 조용하고 그러다보니 좀 저는 밝고 웃는 사람 이었으면 좋겠습니다 | P12: ='Raw data'!Q12 -> 잘 부탁 드립니다
A13: 11 | B13: ='Raw data'!B13 -> 여 | C13: ='Raw data'!C13 -> 곽찬미 | D13: ='Raw data'!F13 -> 37 | E13: ='Raw data'!H13 -> 158 | F13: ='Raw data'!E13 -> 회사원(출판업계) | G13: ='Raw data'!G13 -> 무관 | H13: ='Raw data'!I13 -> 175~ | I13: ='Raw data'!J13 -> ENFJ | J13: ='Raw data'!K13 -> 무관 | K13: ='Raw data'!L13 -> 무교 | L13: ='Raw data'!M13 -> 무관 | M13: ='Raw data'!P13 -> 무관 | N13: ='Raw data'!N13 -> 투명한 사람 | O13: ='Raw data'!O13 -> 대화코드 잘 맞는 분, 선하신 분 | P13: ='Raw data'!Q13 -> 0
A14: 12 | B14: ='Raw data'!#REF! -> #REF! | C14: ='Raw data'!#REF! -> #REF! | D14: ='Raw data'!#REF! -> #REF! | E14: ='Raw data'!#REF! -> #REF! | F14: ='Raw data'!#REF! -> #REF! | G14: ='Raw data'!#REF! -> #REF! | H14: ='Raw data'!#REF! -> #REF! | I14: ='Raw data'!#REF! -> #REF! | ... P14: ='Raw data'!#REF! -> #REF!
A15: 13 | B15: ='Raw data'!B14 -> 남 | C15: ='Raw data'!C14 -> 권민재 | D15: ='Raw data'!F14 -> 34 | E15: ='Raw data'!H14 -> 168 | F15: ='Raw data'!E14 -> 자영업자 (통신업, 법인 임원/개인사업자 대표) | G15: ='Raw data'!G14 -> 28~34 | H15: ='Raw data'!I14 -> ~160 | I15: ='Raw data'!J14 -> ENTJ | J15: ='Raw data'!K14 -> 무관 | K15: ='Raw data'!L14 -> 무교 | L15: ='Raw data'!M14 -> 무관 | M15: ='Raw data'!P14 -> 무관 | N15: ='Raw data'!N14 -> 진취적, 성장과 성공을 목표로 하는 사람 | O15: ='Raw data'!O14 -> 외적, 작고 아담한 스타일 (연예인, 박보영 남보라 윈터) 내적, 든든한 동료로서 미래를 함께 그려나갈 수 있는 분 | P15: ='Raw data'!Q14 -> 베이킹을 통해 인연을 만나는 자리가 있다는걸 처음 알았네요, 좋은 자리 만들어주셔서 감사합니다. 좋은 인연 만날 수 있기를 기원합니다🙏
A16: 14 | B16: ='Raw data'!B15 -> 남 | C16: ='Raw data'!C15 -> 권영훈 | D16: ='Raw data'!F15 -> 43 | E16: ='Raw data'!H15 -> 175 | F16: ='Raw data'!E15 -> 코웰메디 임플란트 / 영업센터장 | G16: ='Raw data'!G15 -> 35~41 | H16: ='Raw data'!I15 -> ~170 | I16: ='Raw data'!J15 -> ISTP | J16: ='Raw data'!K15 -> ISFP, ISTP, ISTJ, ESFP, ESFJ, ESTP, ESTJ | K16: ='Raw data'!L15 -> 무교 | L16: ='Raw data'!M15 -> 무관 | M16: ='Raw data'!P15 -> 병원직군 | N16: ='Raw data'!N15 -> 차분하고 상대의 이야기를 잘 들어주고 배려심 있는 감정의 기복이 크지 않아요. | O16: ='Raw data'!O15 -> 잘 웃고 배려심 있으며 자신만의 독특한 매력이 있는 사람 | P16: ='Raw data'!Q15 -> 업무로 인해 참석이 어려운 날에 배정된다면 변경이 가능한지 궁금합니다
A17: 15 | B17: ='Raw data'!B16 -> 여 | C17: ='Raw data'!C16 -> 김가영 | D17: ='Raw data'!F16 -> 35 | E17: ='Raw data'!H16 -> 152 | F17: ='Raw data'!E16 -> 소품샵 매니저 | G17: ='Raw data'!G16 -> 31~38 | H17: ='Raw data'!I16 -> 170~180 | I17: ='Raw data'!J16 -> ISTP | J17: ='Raw data'!K16 -> 무관 | K17: ='Raw data'!L16 -> 무교 | L17: ='Raw data'!M16 -> 동일, 무관 | M17: ='Raw data'!P16 -> 무관 | N17: ='Raw data'!N16 -> 매너가 좋은 사람 | O17: ='Raw data'!O16 -> 차태현 최우식 | P17: ='Raw data'!Q16 -> 안녕하세요! 제가 직업 특성상 월, 화요일에 쉬어서 이때만 가능합니다
A18: 16 | B18: ='Raw data'!B17 -> 여 | C18: ='Raw data'!C17 -> 김가현 | D18: ='Raw data'!F17 -> 29 | E18: ='Raw data'!H17 -> 160 | F18: ='Raw data'!E17 -> 간호사 | G18: ='Raw data'!G17 -> 24~31 | H18: ='Raw data'!I17 -> 170~180 | I18: ='Raw data'!J17 -> INFP | J18: ='Raw data'!K17 -> 무관 | K18: ='Raw data'!L17 -> 무교 | L18: ='Raw data'!M17 -> 동일 | M18: ='Raw data'!P17 -> 무관 | N18: ='Raw data'!N17 -> 잘 웃고 상대방을 배려하는 사람 | O18: ='Raw data'!O17 -> 귀엽고 다정다감한 사람 + 비흡연자 | P18: ='Raw data'!Q17 -> 0
A19: 17 | B19: ='Raw data'!B18 -> 여 | C19: ='Raw data'!C18 -> 김경선 | D19: ='Raw data'!F18 -> 41 | E19: ='Raw data'!H18 -> 164 | F19: ='Raw data'!E18 -> 시립어린이집교사-주임교사 | G19: ='Raw data'!G18 -> 38~41 | H19: ='Raw data'!I18 -> 175~180 | I19: ='Raw data'!J18 -> ISFP-ISTJ | J19: ='Raw data'!K18 -> 무관 | K19: ='Raw data'!L18 -> 무교 | L19: ='Raw data'!M18 -> 무관 | M19: ='Raw data'!P18 -> 자영업 | N19: ='Raw data'!N18 -> 164에 58-9 통통한 편이고, 참해보인다는 이야기를 종종듣는 인상입노다. 친해지면 털털하고 애교도 있는데, 낮가림이 있어 먼저 다가가 편해지는데 시간을 필요로 합니다. 올곧게 바르게 살았고, 앞으로도 그럴 예정입니다. 여행을 좋아하고 맛있는걸 좋아합니다^^ | O19: ='Raw data'!O18 -> 너무 감수성이 높은 사람은 잘 안맞는것 같아요.유쾌하고 투명한 사람이 좋습니다. 성실한 사람이 좋습니다.노담이면 좋지만 아니어도 상관없고, 문신은 어려울것같습니다. | P19: ='Raw data'!Q18 -> 0
A20: 18 | B20: ='Raw data'!B19 -> 여 | C20: ='Raw data'!C19 -> 김경희 | D20: ='Raw data'!F19 -> 38 | E20: ='Raw data'!H19 -> 161 | F20: ='Raw data'!E19 -> 부산대학병원 간호부 | G20: ='Raw data'!G19 -> 35~41 | H20: ='Raw data'!I19 -> 170~ | I20: ='Raw data'!J19 -> ESFJ | J20: ='Raw data'!K19 -> 무관 | K20: ='Raw data'!L19 -> 무교 | L20: ='Raw data'!M19 -> 동일 | M20: ='Raw data'!P19 -> 자영업 | N20: ='Raw data'!N19 -> 차분함, 다정함, 꾸준함, 혼자서도 시간 잘 보냄 | O20: ='Raw data'!O19 -> 다정, 안정적인분 | P20: ='Raw data'!Q19 -> 0
A21: 19 | B21: ='Raw data'!B20 -> 남 | C21: ='Raw data'!C20 -> 김광민 | D21: ='Raw data'!F20 -> 28 | E21: ='Raw data'!H20 -> 181 | F21: ='Raw data'!E20 -> 회사원(플랫폼업체 영업직) | G21: ='Raw data'!G20 -> 28~31 | H21: ='Raw data'!I20 -> 160~170 | I21: ='Raw data'!J20 -> ISFJ | J21: ='Raw data'!K20 -> 무관 | K21: ='Raw data'!L20 -> 무교 | L21: ='Raw data'!M20 -> 무관 | M21: ='Raw data'!P20 -> 무관 | N21: ='Raw data'!N20 -> 상대방에게 웃음을 주는 게 좋고 일상 대화를 하면서 평일에 받았던 스트레스가 풀리기도 합니다 처음에는 어색해하기도 하고 낯도 많이 가리기도 하지만 몇 번 얘기하다 보면 어색함도 풀리고 더 말을 걸고 있기도 합니다 일과 생활이 완벽하게 분리가 되어있어 일할 때는 일만 하고 쉴 때는 절대 일 생각도 안 하고 일 얘기도 안 하고 살아가고 있습니다 취미는 야구를 보러 다니고 주말 아침에 축구를 하러 나가고 있습니다 야구를 같이 보러 다니는 걸 좋아하며 맛있는 음식점이 생각나면 찾아가는것도 좋아합니다 집 데이트와 밖에서 하는 데이트를 한쪽으로 몰리지 않게 하는 걸 좋아합니다 연애 스타일은 주도적인 편은 아닌 거 같고 상대방에게 맞춰주는 편입니다 뭘 하든 대화를 통해 하려고 하며 싸우더라도 대화로 바로 푸는 스타일이며 한번 좋아하기 시작하면 정말 정말 많이 좋아하는 타입입니다 | O21: ='Raw data'!O20 -> 안정적이며 대화가 잘 통하는 사람 연상이면 더 좋을거같고 연하는 선호하지 않습니다 | P21: ='Raw data'!Q20 -> 0
A22: 20 | B22: ='Raw data'!B21 -> 여 | C22: ='Raw data'!C21 -> 김나영 | D22: ='Raw data'!F21 -> 26 | E22: ='Raw data'!H21 -> 161 | F22: ='Raw data'!E21 -> (직장)어린이집 교사 | G22: ='Raw data'!G21 -> 20~31 | H22: ='Raw data'!I21 -> 170~ | I22: ='Raw data'!J21 -> ISFJ | J22: ='Raw data'!K21 -> ISFP, ISTP, INFJ, ISTJ, INTJ, ISFJ, ESFP, ENFJ, ESFJ, ENTP, ESTP, ENTJ, ESTJ | K22: ='Raw data'!L21 -> 기독교 | L22: ='Raw data'!M21 -> 동일, 무관 | M22: ='Raw data'!P21 -> 무관 | N22: ='Raw data'!N21 -> 처음 볼 때 낯가림이 있어 조금 뚝닥대고 차가워보일 수 있으나 사람 좋아하고 정이 많음. 집순이, 남사친 X 외적으로 통통한 편.. 빵 좋아하고 작고 귀여운 것들 좋아함. 최애 캐릭터는 짱구,, 입니다. | O22: ='Raw data'!O21 -> 담배, 문신 X / 키 175 이상에 직업 있고 자기 일 열심히 하는 사람. 안경은 약간 비선호.. 무쌍이나 얇은 유쌍 선호(아랍 보다는 두부 선호) 마른 체형보다는 조금 덩치가 있는 분 선호(근육질X) | P22: ='Raw data'!Q21 -> 0
A23: 21 | B23: ='Raw data'!B22 -> 여 | C23: ='Raw data'!C22 -> 김다슬 | D23: ='Raw data'!F22 -> 29 | E23: ='Raw data'!H22 -> 164 | F23: ='Raw data'!E22 -> 신라스테이 경영지원 | G23: ='Raw data'!G22 -> 31~34 | H23: ='Raw data'!I22 -> 175~ | I23: ='Raw data'!J22 -> ESTJ/ ESTP | J23: ='Raw data'!K22 -> 무관, INFP, ISFP, INFJ, ISFJ, ENFP, ESFP, ENFJ, ESFJ | K23: ='Raw data'!L22 -> 무교 | L23: ='Raw data'!M22 -> 동일, 무관 | M23: ='Raw data'!P22 -> 병원직군, 공무원 | N23: ='Raw data'!N22 -> 외관상 도도해보여 다가가기 어려워보이나 내면은 순딩순딩 친해지면 첫인상과 전혀 다른 마음 따뜻한 사람 | O23: ='Raw data'!O22 -> 키큰 강아지상 | P23: ='Raw data'!Q22 -> 0
A24: 22 | B24: ='Raw data'!B23 -> 남 | C24: ='Raw data'!C23 -> 김동국 | D24: ='Raw data'!F23 -> 37 | E24: ='Raw data'!H23 -> 174 | F24: ='Raw data'!E23 -> 대학병원 행정직 | G24: ='Raw data'!G23 -> 28~38 | H24: ='Raw data'!I23 -> 160~170 | I24: ='Raw data'!J23 -> ISTP | J24: ='Raw data'!K23 -> 무관 | K24: ='Raw data'!L23 -> 천주교 | L24: ='Raw data'!M23 -> 무관 | M24: ='Raw data'!P23 -> 무관 | N24: ='Raw data'!N23 -> 다정하고 잘 챙겨주는사람 | O24: ='Raw data'!O23 -> 청순하고 털털하신분 | P24: ='Raw data'!Q23 -> 0
A25: 23 | B25: ='Raw data'!B24 -> 남 | C25: ='Raw data'!C24 -> 김문환 | D25: ='Raw data'!F24 -> 40 | E25: ='Raw data'!H24 -> 176 | F25: ='Raw data'!E24 -> 작가, 철학연구가 | G25: ='Raw data'!G24 -> 31~41 | H25: ='Raw data'!I24 -> 160~170 | I25: ='Raw data'!J24 -> ENTP | J25: ='Raw data'!K24 -> 무관 | K25: ='Raw data'!L24 -> 무교 | L25: ='Raw data'!M24 -> 무관 | M25: ='Raw data'!P24 -> 무관 | N25: ='Raw data'!N24 -> 장난기 많지만 진중한 사람 | O25: ='Raw data'!O24 -> 0 | P25: ='Raw data'!Q24 -> 0
A26: 24 | B26: ='Raw data'!B25 -> 여 | C26: ='Raw data'!C25 -> 김민경 | D26: ='Raw data'!F25 -> 32 | E26: ='Raw data'!H25 -> 171 | F26: ='Raw data'!E25 -> 대기업계열사, 사이버 보안 | G26: ='Raw data'!G25 -> 31~34 | H26: ='Raw data'!I25 -> 175~180 | I26: ='Raw data'!J25 -> ENFP | J26: ='Raw data'!K25 -> 무관 | K26: ='Raw data'!L25 -> 불교 | L26: ='Raw data'!M25 -> 무관 | M26: ='Raw data'!P25 -> 자영업 | N26: ='Raw data'!N25 -> 잘웃고 리액션 장인이라는 소리를 많이 들어요 | O26: ='Raw data'!O25 -> 제 키를 부담스러워하지 않는 사람, 말을 예쁘게 하는 사람 | P26: ='Raw data'!Q25 -> 0
... A88: 86 | B88: ='Raw data'!B87 -> 여 | C88: ='Raw data'!C87 -> 배민정 | D88: ='Raw data'!F87 -> 39 | E88: ='Raw data'!H87 -> 165 | F88: ='Raw data'!E87 -> 현대모비스 진천공장 | G88: ='Raw data'!G87 -> 38~41 | H88: ='Raw data'!I87 -> 무관 | I88: ='Raw data'!J87 -> ENTP | J88: ='Raw data'!K87 -> INFP, INTP, INFJ, INTJ, ENFP, ENFJ, ENTP, ENTJ | K88: ='Raw data'!L87 -> 무교 | L88: ='Raw data'!M87 -> 무관 | M88: ='Raw data'!P87 -> 무관 | N88: ='Raw data'!N87 -> 감정이 얼굴에 들어날 정도로 약간 솔직한편 입니다. (남에 대한것이 아닌 제 감정에 솔직히 말하는편) 말로 서로 조율하는걸 선호 하는 편 입니다. 성격은 약간 테토스러운 면이 있습니다 먼저 사과하고 먼저 연락 잘 합니다 | O88: ='Raw data'!O87 -> 느낌이 좋고 말이 잘 통하며 유머가 있었으면 합니다 | P88: ='Raw data'!Q87 -> 특이사항 없습니다. 아 지방사람이라 주말에만 가능 합니다
A89: 87 | B89: ='Raw data'!#REF! -> #REF! | C89: ='Raw data'!#REF! -> #REF! | D89: ='Raw data'!#REF! -> #REF! | E89: ='Raw data'!#REF! -> #REF! | F89: ='Raw data'!#REF! -> #REF! | G89: ='Raw data'!#REF! -> #REF! | H89: ='Raw data'!#REF! -> #REF! | I89: ='Raw data'!#REF! -> #REF! | ... P89: ='Raw data'!#REF! -> #REF!
A90: 88 | B90: ='Raw data'!B88 -> 여 | C90: ='Raw data'!C88 -> 백엄지 | D90: ='Raw data'!F88 -> 35 | E90: ='Raw data'!H88 -> 168 | F90: ='Raw data'!E88 -> 트로트백업댄서 | G90: ='Raw data'!G88 -> 31~41 | H90: ='Raw data'!I88 -> 175~ | I90: ='Raw data'!J88 -> INTP | J90: ='Raw data'!K88 -> INTP, INFJ, ISTJ, INTJ, ISFJ, ENFJ, ENTJ | K90: ='Raw data'!L88 -> 무교 | L90: ='Raw data'!M88 -> 무관 | M90: ='Raw data'!P88 -> 무관 | N90: ='Raw data'!N88 -> 긍정적이고 밝은사람 매사 진지한 편이고 토론을 좋아함 | O90: ='Raw data'!O88 -> 내가 배울수있는 존경할만한 사람 | P90: ='Raw data'!Q88 -> 0
A91: 89 | B91: ='Raw data'!B89 -> 여 | C91: ='Raw data'!C89 -> 서다빈 | D91: ='Raw data'!F89 -> 28 | E91: ='Raw data'!H89 -> 158 | F91: ='Raw data'!E89 -> 사회복지사(장애인 자립생활센터) | G91: ='Raw data'!G89 -> 24~34 | H91: ='Raw data'!I89 -> 175~ | I91: ='Raw data'!J89 -> INT(F)P | J91: ='Raw data'!K89 -> 무관, ESFJ | K91: ='Raw data'!L89 -> 기독교 | L91: ='Raw data'!M89 -> 동일 | M91: ='Raw data'!P89 -> 병원직군, 기술직, 공무원, 연구직, 회사원, 무관 | N91: ='Raw data'!N89 -> 귀여운 사람 | O91: ='Raw data'!O89 -> 쩝쩝거리지 않고 주먹으로 젓가락질 하지 않는 사람 | P91: ='Raw data'!Q89 -> 0
A92: 90 | B92: ='Raw data'!B90 -> 여 | C92: ='Raw data'!C90 -> 서지연 | D92: ='Raw data'!F90 -> 36 | E92: ='Raw data'!H90 -> 164 | F92: ='Raw data'!E90 -> 사무직(티빙/광고사업부) | G92: ='Raw data'!G90 -> 35~41 | H92: ='Raw data'!I90 -> 175~ | I92: ='Raw data'!J90 -> ENTJ | J92: ='Raw data'!K90 -> 무관 | K92: ='Raw data'!L90 -> 무교 | L92: ='Raw data'!M90 -> 동일 | M92: ='Raw data'!P90 -> 기술직, 공무원 | N92: ='Raw data'!N90 -> 처음엔 낯을 가리지만 친해지면 털털 | O92: ='Raw data'!O90 -> 다정하고 가볍지 않은 사람 | P92: ='Raw data'!Q90 -> 0
A93: 91 | B93: ='Raw data'!B91 -> 남 | C93: ='Raw data'!C91 -> 서현석 | D93: ='Raw data'!F91 -> 34 | E93: ='Raw data'!H91 -> 168 | F93: ='Raw data'!E91 -> 소프트웨어 개발자(RSQUARE 홈닷FE) | G93: ='Raw data'!G91 -> 28~34 | H93: ='Raw data'!I91 -> ~165 | I93: ='Raw data'!J91 -> ENFJ | J93: ='Raw data'!K91 -> 무관 | K93: ='Raw data'!L91 -> 무교 | L93: ='Raw data'!M91 -> 동일 | M93: ='Raw data'!P91 -> 무관 | N93: ='Raw data'!N91 -> 평소에 성실하고 섬세하다는 말을 많이 듣습니다. | O93: ='Raw data'!O91 -> 관계 유지에 노력을 기울이는 사람을 선호합니다. 외적으로는 작고 귀여운 두부상 스타일 좋아합니다. | P93: ='Raw data'!Q91 -> 0
A94: 92 | B94: ='Raw data'!B92 -> 여 | C94: ='Raw data'!C92 -> 성은진 | D94: ='Raw data'!F92 -> 29 | E94: ='Raw data'!H92 -> 162 | F94: ='Raw data'!E92 -> 대학병원 의료기사 | G94: ='Raw data'!G92 -> 28~34 | H94: ='Raw data'!I92 -> 175~ | I94: ='Raw data'!J92 -> ESFJ | J94: ='Raw data'!K92 -> 무관 | K94: ='Raw data'!L92 -> 무교, 천주교 | L94: ='Raw data'!M92 -> 무관 | M94: ='Raw data'!P92 -> 무관 | N94: ='Raw data'!N92 -> 자기관리를 잘하고 성격은 밝고 긍정적이며 책임감 있고 배려심 많음 | O94: ='Raw data'!O92 -> 다정하고 배려심 많으며 배울 점이 많고 안정감이 드는 사람 | P94: ='Raw data'!Q92 -> 잘부탁드립니다!!!
A95: 93 | B95: ='Raw data'!B93 -> 여 | C95: ='Raw data'!C93 -> 성지원 | D95: ='Raw data'!F93 -> 44 | E95: ='Raw data'!H93 -> 165 | F95: ='Raw data'!E93 -> 서울장곡초등학교 교사 | G95: ='Raw data'!G93 -> 38~ | H95: ='Raw data'!I93 -> 170~ | I95: ='Raw data'!J93 -> ISTJ | J95: ='Raw data'!K93 -> 무관, ISTJ, ISFJ, ESTJ | K95: ='Raw data'!L93 -> 무교 | L95: ='Raw data'!M93 -> 무관 | M95: ='Raw data'!P93 -> 병원직군, 연구직, 회사원 | N95: ='Raw data'!N93 -> 차분하고 친해지면 귀여운 매력 | O95: ='Raw data'!O93 -> 심신이 건강한 사람 | P95: ='Raw data'!Q93 -> 0
A96: 94 | B96: ='Raw data'!B94 -> 남 | C96: ='Raw data'!C94 -> 소혜민 | D96: ='Raw data'!F94 -> 32 | E96: ='Raw data'!H94 -> 175 | F96: ='Raw data'!E94 -> 자영업 | G96: ='Raw data'!G94 -> 24~31 | H96: ='Raw data'!I94 -> 160~170 | I96: ='Raw data'!J94 -> ENFP | J96: ='Raw data'!K94 -> 무관 | K96: ='Raw data'!L94 -> 무교 | L96: ='Raw data'!M94 -> 무관 | M96: ='Raw data'!P94 -> 무관 | N96: ='Raw data'!N94 -> 긍정적이고 센스있다 | O96: ='Raw data'!O94 -> 긴머리 유쌍 예의 있으신분 | P96: ='Raw data'!Q94 -> 0
A97: 95 | B97: ='Raw data'!B95 -> 남 | C97: ='Raw data'!C95 -> 손종민 | D97: ='Raw data'!F95 -> 45 | E97: ='Raw data'!H95 -> 173 | F97: ='Raw data'!E95 -> 학원강사 (초중고) | G97: ='Raw data'!G95 -> 무관 | H97: ='Raw data'!I95 -> 무관 | I97: ='Raw data'!J95 -> INFP | J97: ='Raw data'!K95 -> 무관 | K97: ='Raw data'!L95 -> 기독교 | L97: ='Raw data'!M95 -> 동일 | M97: ='Raw data'!P95 -> 무관 | N97: ='Raw data'!N95 -> 착함(진짜) (타칭) | O97: ='Raw data'!O95 -> 귀여운(but 무관) | P97: ='Raw data'!Q95 -> 시간이 어떻게되는지 모르겠네요ㅠ
A98: 96 | B98: ='Raw data'!B96 -> 여 | C98: ='Raw data'!C96 -> 손진 | D98: ='Raw data'!F96 -> 31 | E98: ='Raw data'!H96 -> 165 | F98: ='Raw data'!E96 -> 패션업 / 마케팅 | G98: ='Raw data'!G96 -> 31~34 | H98: ='Raw data'!I96 -> 175~ | I98: ='Raw data'!J96 -> ESFP | J98: ='Raw data'!K96 -> 무관 | K98: ='Raw data'!L96 -> 무교 | L98: ='Raw data'!M96 -> 동일 | M98: ='Raw data'!P96 -> 무관 | N98: ='Raw data'!N96 -> 텐션은 있는데 감정은 안정된 사람 | O98: ='Raw data'!O96 -> 대화가 통하고, 삶의 결이 어느 정도 자리 잡힌 사람 | P98: ='Raw data'!Q96 -> 0
A99: 97 | B99: ='Raw data'!B97 -> 여 | C99: ='Raw data'!C97 -> 송수연 | D99: ='Raw data'!F97 -> 36 | E99: ='Raw data'!H97 -> 166 | F99: ='Raw data'!E97 -> 필라테스 강사 | G99: ='Raw data'!G97 -> 31~38 | H99: ='Raw data'!I97 -> 170~ | I99: ='Raw data'!J97 -> ESTJ | J99: ='Raw data'!K97 -> 무관 | K99: ='Raw data'!L97 -> 무교 | L99: ='Raw data'!M97 -> 동일 | M99: ='Raw data'!P97 -> 자영업, 무관 | N99: ='Raw data'!N97 -> 바르고 자기관리 잘하고 거짓말,내숭 없는 사람이에요! 베이킹 하는걸 좋아해서 원데이 클래스를 많이 다녀봤어요! 항상 열심히하고 제 일에 자부심을 가지고 사는 사람입니다 :) 오래 회사생활 하다가 이직한거라 굉장히 긍정적으로 활발하게 공부하며 살고있어요! | O99: ='Raw data'!O97 -> 깔끔하고 다정하고 센스있는 분을 좋아해요! 예의있으면서 상대방한테 맞는 배려가 뭔지 아는 너드남 스타일🩷 | P99: ='Raw data'!Q97 -> 무조건 안된다는 아니지만 enfj entp enfp 분들이랑은 별로 안맞았던 것 같아서 좀 만나기 두려워요 😂
A100: 98 | B100: ='Raw data'!B98 -> 여 | C100: ='Raw data'!C98 -> 송아현 | D100: ='Raw data'!F98 -> 29 | E100: ='Raw data'!H98 -> 172 | F100: ='Raw data'!E98 -> 자산운용사 | G100: ='Raw data'!G98 -> 31~38 | H100: ='Raw data'!I98 -> 175~ | I100: ='Raw data'!J98 -> INTJ | J100: ='Raw data'!K98 -> ENFJ, ESFJ, ENTJ, ESTJ | K100: ='Raw data'!L98 -> 무교 | L100: ='Raw data'!M98 -> 무관 | M100: ='Raw data'!P98 -> 공무원 | N100: ='Raw data'!N98 -> 차분하고 열심히 사는 사람 | O100: ='Raw data'!O98 -> 예의바르고 열심히 사는 사람 | P100: ='Raw data'!Q98 -> 0
A101: 99 | B101: ='Raw data'!B99 -> 여 | C101: ='Raw data'!C99 -> 신영랑 | D101: ='Raw data'!F99 -> 39 | E101: ='Raw data'!H99 -> 163 | F101: ='Raw data'!E99 -> 공무원 | G101: ='Raw data'!G99 -> 35~38 | H101: ='Raw data'!I99 -> 175~180 | I101: ='Raw data'!J99 -> ISFP | J101: ='Raw data'!K99 -> 무관 | K101: ='Raw data'!L99 -> 무교 | L101: ='Raw data'!M99 -> 동일 | M101: ='Raw data'!P99 -> 무관 | N101: ='Raw data'!N99 -> 솔직하고 신뢰를 중시하는 사람 | O101: ='Raw data'!O99 -> 다정하고 재밋는 사람 | P101: ='Raw data'!Q99 -> 0
... A130: 128 | B130: ='Raw data'!B128 -> 남 | C130: ='Raw data'!C128 -> 이민규 | D130: ='Raw data'!F128 -> 34 | E130: ='Raw data'!H128 -> 185 | F130: ='Raw data'!E128 -> 외국계 IT 기업 / PM | G130: ='Raw data'!G128 -> 28~34 | H130: ='Raw data'!I128 -> 160~170 | I130: ='Raw data'!J128 -> INFP | J130: ='Raw data'!K128 -> 무관 | K130: ='Raw data'!L128 -> 무교 | L130: ='Raw data'!M128 -> 동일 | M130: ='Raw data'!P128 -> 무관 | N130: ='Raw data'!N128 -> 저는 운동 좋아하고 대화하고 서로 일상 공유하는 것도 좋습니다. 본인 일에 최선을 다하고 데이트할 땐 데이트에 집중하는 성향을 가지고 있습니다 | O130: ='Raw data'!O128 -> 대화 잘 통하고 선하게 생기신 분 | P130: ='Raw data'!Q128 -> 0
...

Sheet 인원선정 종합
A1: No. | B1: 상시 | C1: 10일M | D1: 10일A | E1: 16일M | F1: 16일A | G1: 성별 | H1: 이름 | I1: 나이 | J1: 키 | K1: 직업(직장과 파트) | L1: 선호나이 | M1: 선호 키 | N1: MBTI | O1: 선호 MBTI | P1: 종교 | Q1: 상대 - 선호종교 | R1: 비선호 직군 | S1: 간단한 자기소개 | T1: 이상형 | U1: 건의사항
A2: 381 | D2: 1 | G2: 여 | H2: 김지연 | I2: 20 | J2: 155 | K2: 대학생 | L2: 20~27 | M2: 170~ | N2: Istp | O2: 무관 | P2: 무교 | Q2: 무관 | R2: 무관 | S2: 처음엔 어색해서 말도 잘 못걸고 뚝딱거리긴 하지만 조금씩 편해지면 말 많아져요!! | T2: 스스로를 잘 어울리게 꾸밀줄 아는 사람 | U2: 0
A3: 354 | G3: 여 | H3: 테스 | I3: 21 | J3: 162 | K3: 모델 | L3: 20~45 | M3: 160~ | N3: INFP | O3: 무관 | P3: 무교 | Q3: 동일 | R3: 무관 | S3: 프랑스 여자 | T3: 0 | U3: 0
A4: 120 | B4: 1 | G4: 여 | H4: 윤예은 | I4: 23 | J4: 168 | K4: 댄서 | L4: 24~27 | M4: 175~ | N4: ENFP | O4: INFP, INFJ, ENFP, ESFP, ENFJ | P4: 무교, 기독교 | Q4: 동일 | R4: 무관 | S4: 웃음이 많고 밝으면서 매너있고 긍정적인 사람입니다! | T4: 키가 크시고 다정한 성격이랑 말투를 가지신 분을 좋아하고 강아지상에 비흡연자이신분을 좋아합니다! | U4: 이상형에 부합하는 분이 나오셨으면 하는 바람이 있습니다:) ,,!!
A5: 281 | G5: 남 | H5: 김동영 | I5: 24 | J5: 168 | K5: 서울도시가스 / 안전관리 | L5: 24~27 | M5: ~165 | N5: ENFJ | O5: 무관 | P5: 0 | Q5: 무관 | R5: 무관 | S5: 밝고 긍정적인 사람입니다. 웃음이 많고 처음 보는 사람과도 빠르게 친해질 수 있습니다. | T5: 두부상 | U5: 0
A6: 165 | G6: 여 | H6: 장지현 | I6: 25 | J6: 168 | K6: 치과위생사 | L6: 24~31 | M6: 175~ | N6: isfp | O6: ENFJ, ESFJ | P6: 무교 | Q6: 동일 | R6: 자영업 | S6: 낯을 좀 가리지만 친해지면 재밌고 엉뚱한사람 ! | T6: 0 | U6: 0
A7: 373 | B7: 1 | G7: 남 | H7: 남윤모 | I7: 26 | J7: 174 | K7: 외국계회사 공무부 안전관리자 | L7: 24~31 | M7: ~170 | N7: istj | O7: 무관 | P7: 기독교 | Q7: 무관 | R7: 무관 | S7: 신중하고 유쾌한사람 | T7: 활발한사람 | U7: 감사합니다. !
A8: 55 | G8: 남 | H8: 김응혁 | I8: 26 | J8: 175 | K8: 향수매장 직원 | L8: 24~31 | M8: ~165 | N8: istj | O8: 무관 | P8: 무교 | Q8: 무관 | R8: 병원직군 | S8: 솔직한 사람 | T8: 기댈수있는 사람 | U8: 잘부탁드립니다!
A9: 41 | B9: 1 | G9: 여 | H9: 김수경 | I9: 26 | J9: 171 | K9: 보령 제약회사, 학술팀 | L9: 24~34 | M9: 180~ | N9: INTP, ISTP 둘다 나와요 | O9: ISTJ, INTJ, ISFJ, ESFJ, ESTP, ENTJ, ESTJ | P9: 무교 | Q9: 동일 | R9: 자영업 | S9: 처음에는 낯을 가리는데 1:1로 보면 말을 많이 하는 사람인것 같아요〰 털털한 것 같고 사람들을 웃기는 걸 좋아하는데 또 저도 잘 웃는 것 같습니다. 운동을 좋아하고 잘하는 편이에요 | T9: 외적인건 코가 예쁘고 눈이 날카롭지 않은 사람이 좋은 것 같아요. 내적으로는 똑똑하고 지혜롭고 감정기복 없고 성실한 사람이 좋습니다. 잘 웃는 사람도 좋아요! | U9: 0
A10: 307 | B10: 1 | G10: 여 | H10: 박서영 | I10: 26 | J10: 168 | K10: 삼성서울병원 별관동 수술실 | L10: 24~31 | M10: 175~ | N10: ISFJ | O10: 무관 | P10: 무교 | Q10: 동일 | R10: 병원직군 | S10: 밝고 웃음이 많은 사람입니다 ◡̈ | T10: 키 크고 얘기가 잘 통하며 예의바르고 다정다감한 사람 | U10: 0
A11: 305 | B11: 1 | G11: 여 | H11: 박세란 | I11: 26 | J11: 164 | K11: 삼성서울병원 건강의학본부 임상병리사 | L11: 24~31 | M11: 170~ | N11: ISFJ | O11: 무관 | P11: 무교 | Q11: 동일, 무관 | R11: 자영업 | S11: 배려, 차분, 리액션 퀸 | T11: 따뜻, 섬세, 안정형 | U11: 0
A12: 350 | B12: 1 | G12: 여 | H12: 서다솜 | I12: 26 | J12: 164 | K12: 치과위생사 | L12: 24~31 | M12: 175~ | N12: ESFP | O12: INFP, ISFP, ISTP, INFJ, ISTJ, INTJ, ISFJ, ENTP | P12: 무교 | Q12: 동일 | R12: 무관 | S12: 밝고 도전을 좋아하는 사람 | T12: 도전적이고, 자기 할 일에 열정적인 사람 / 나한테만 다정한 사람 | U12: 0
A13: 257 | G13: 여 | H13: 오영경 | I13: 26 | J13: 160 | K13: 회계 공무직 | L13: 28~34 | M13: 175~ | N13: infp | O13: 무관 | P13: 무교 | Q13: 무관 | R13: 공무원 | S13: 조용함
A14: 107 | G14: 여 | H14: 양예림 | I14: 26 | J14: 160 | K14: 치기공사 | L14: 24~31 | M14: 175~180 | N14: Esfp | O14: ESFJ | P14: 무교, 기독교 | Q14: 무관 | R14: 병원직군, 연구직, 회사원 | S14: 재밌고 통통튀는 사람 | T14: 단정하고 구릿빛 피부 웃기고 다정한사람 | U14: 0
A15: 233 | G15: 여 | H15: 허예진 | I15: 26 | J15: 168 | K15: 요양병원 간호사 | L15: 24~31 | M15: 175~ | N15: INTJ | O15: 무관 | P15: 무교 | Q15: 무관 | R15: 자영업 | S15: 친해지면 재밌는 사람 | T15: 정형화 된 것은 없고 서로 얼굴 이미지가 같고 대화가 통하는 사람?? | U15: 0
A16: 20 | G16: 여 | H16: 김나영 | I16: 26 | J16: 161 | K16: (직장)어린이집 교사 | L16: 20~31 | M16: 170~ | N16: isfj | O16: ISFP, ISTP, INFJ, ISTJ, INTJ, ISFJ, ESFP, ENFJ, ESFJ, ENTP, ESTP, ENTJ, ESTJ | P16: 기독교 | Q16: 동일, 무관 | R16: 무관 | S16: 처음 볼 때 낯가림이 있어 조금 뚝닥대고 차가워보일 수 있으나 사람 좋아하고 정이 많음. 집순이, 남사친 X 외적으로 통통한 편.. 빵 좋아하고 작고 귀여운 것들 좋아함. 최애 캐릭터는 짱구,, 입니다. | T16: 담배, 문신 X / 키 175 이상에 직업 있고 자기 일 열심히 하는 사람. 안경은 약간 비선호.. 무쌍이나 얇은 유쌍 선호(아랍 보다는 두부 선호) 마른 체형보다는 조금 덩치가 있는 분 선호(근육질X) | U16: 0
A17: 77 | G17: 여 | H17: 박예령 | I17: 26 | J17: 155 | K17: 간호학과 졸업 후 취업 대기중입니다! | L17: 24~34 | M17: 170~ | N17: ESTP | O17: INFP, ISFP, INFJ, ISTJ, INTJ, ISFJ, ENFP, ESFP, ENFJ, ESFJ, ENTP, ESTP, ENTJ, ESTJ | P17: 무교 | Q17: 무관 | R17: 무관 | S17: 밝고 텐션 높아요! 무던하고 뒤끝없고 즉흥적인 면이 있어요! 특별히 싫어하는 일이 아니면 상대 취미도 함께 해주고 같이 추억만드는걸 좋아해요. 성격은 조금 빠른편인것 같고 자기자신을 꾸미는 것을 좋아합니당 | T17: 외적으로는 뚱뚱하지 않은 체형에 순한 인상이나 반장했을것 같은 반듯한 사람을 좋아합니다! 내적으로는 나를 웃겨줄수 있는 센스와 재치가 있었으면 좋겠어요! 친구같은 연애하는것을 추구하고 연락이나 만남횟수 같은것에 효율따지지 않고 최선을 다하는 연애하는 사람이 좋아요 | U17: 0
A18: 3 | G18: 남 | H18: 강병규 | I18: 27 | J18: 172 | K18: 디스플레이허브 기술파트 | L18: 20~27 | M18: ~165 | N18: ENTJ | O18: 무관 | P18: 기독교 | Q18: 동일, 무관 | R18: 무관 | S18: 항상 긍정적으로 살아가려고 노력하고 굴곡이 맞지 않은 사람 | T18: 베이지가 잘 어울리는 여자 | U18: 0
A19: 174 | G19: 남 | H19: 정지동 | I19: 27 | J19: 172 | K19: 반도체 장비 프로그래머 | L19: 24~27 | M19: ~165 | N19: ESTP | O19: 무관 | P19: 천주교 | Q19: 무관 | R19: 무관 | S19: 현실적이며 이성적이다, 감정의 폭이 크지 않으며 낯을 가리는 편이다. 하지만 좀 친해지면 재밌게 잘 하는 것 같다. 사람이 너무 많으면 말을 잘 못하는 편이며 오히려 소수일수록 편하게 말하는 것 같다. 친할수록 현실적으로 해결책을 같이 고민하며 오히려 낯선 사람은 공감을 잘 해주는 것 같다. | T19: 예의바르고 너무 감정적이지 않으며 반묶음 잘 어울리는분 | U19: 0
A20: 340 | G20: 남 | H20: 이정현 | I20: 27 | J20: 183 | K20: 삼성서울병원/ 보안팀 | L20: 20~31 | M20: ~175 | N20: ISTJ | O20: 무관 | P20: 기독교 | Q20: 무관 | R20: 외적으로는 반묶음 잘 어울리시는 귀여운 사람. 내적으로는 대화 잘 통하고 예의있는 사람! | S20: 0 | T20: 평소엔 조용하지만 편해지면 생각보다 수다스럽고 장난기도 많아요. 꾸준히 운동하면서 스스로를 관리하려고 노력 중입니다. 사람 사이에서는 예의와 배려를 가장 중요하게 생각합니다. | U20: 이번달이 어려우면 다음달도 한 번 참여해보고싶습니다.
A21: 212 | B21: 1 | G21: 여 | H21: 김보영 | I21: 27 | J21: 156 | K21: 삼성서울병원/영상의학과 사무직 | L21: 20~30 | M21: 175~ | N21: ESTJ | O21: 무관 | P21: 무교 | Q21: 동일 | R21: 0 | S21: 저는 스포츠를 좋아해요. 그 중 e스포츠를 가장 좋아합니다! Lck를 사랑하는 사람이에요. 게임을 하는 것도, 보는 것도 좋아합니다. 여행다니는 것도 좋아해요. 이곳저곳 다니면서 힐링을 합니다. 사람이랑 대화하는 것도 좋아해서 새로운 만남이 있으면 좋아합니다. 항상 밝고 낯을 가리지 않는 그런 사람이에요 | T21: 0 | U21: 0
A22: 193 | B22: 1 | G22: 여 | H22: 최윤지 | I22: 27 | J22: 165 | K22: CJ_무대감독 | L22: 24~34 | M22: 175~ | N22: ESTP | O22: ISFP, ESFP, ESFJ | P22: 무교 | Q22: 동일 | R22: 자영업 | S22: 긍정적인 에너지를 가진 사람 술, 담배 안하고 타투 X /운동 헬스 필라테스 병행 중 회사 경력 5년차, 한 곳에 꾸준히 일할 수 있는 인내심 보유 T긴 하지만 애교 많고 리액션 잘하는 다정한 타입이에요 사람들과 대화하고 소통하는 일을 하고 있어서 처음봐도 어색함 없이 대하는 걸 잘해요 어딜가도 적응력이 좋아요 츄 닮았다고 자주 들어요..^,,^ 하하 | T22: 감자상 공룡상, 술,담배,타투 X 운동하고 근육덩치가 있으신 분, 말 예쁘게 하는 사람, 건실한 사람 | U22: 안녕하세요 운영진님 직업에서 직업군인은 피하고 싶어요..! 제가 직업이 방송쪽이라 교대근무여서 교대근무가 괜찮으신 분이면 좋겠습니다 좋은 사람으로 잘부탁드립니다~! 감사해요🩶
A23: 331 | B23: 1 | G23: 여 | H23: 이지현 | I23: 27 | J23: 164 | K23: 보건직 | L23: 28~34 | M23: 175~ | N23: ESFJ | O23: ENTJ제외 | P23: 무교 | Q23: 동일 | R23: 병원직군, 자영업 | S23: 상대에게 잘 맞춰줄 수 있고, 활발하고 다양한 경험을 하는걸 좋아합니다. 스키, 수영, 등산 | T23: 다정다감, 성숙한, 회피형 싫고, 예의바른,
A24: 341 | B24: 1 | G24: 여 | H24: 추수진 | I24: 27 | J24: 167 | K24: 중학교 교사 | L24: 28~31 | M24: 175~180 | N24: ISFP | O24: 무관, ESFP, ESTP | P24: 무교 | Q24: 동일, 무관 | R24: 공무원, 연구직, 회사원 | S24: 밝은 에너지가 있는 건강한 사람 | T24: 175이상 밝은 긍정적인 사람 | U24: 0
A25: 145 | G25: 여 | H25: 이윤선 | I25: 27 | J25: 153 | K25: 간호사 | L25: 28~34 | M25: 170~ | N25: ESFJ | O25: 무관 | P25: 무교 | Q25: 동일 | R25: 무관 | S25: 밝고 배려심있는 따뜻한사람 + 여행을 좋아함 | T25: 듬직하고, 성실하고, 재미있는 사람 + 비흡연자 선호 | U25: 0
A26: 253 | G26: 여 | H26: 구한나 | I26: 27 | J26: 163 | K26: 치위생사 | L26: 28~31 | M26: 170~180 | N26: infj | O26: 무관 | P26: 무교 | Q26: 동일 | R26: 병원직군, 기술직, 공무원, 연구직, 회사원 | S26: 직접 알아보기🥰 | T26: 웃는게 이쁘고 재밌는 사람
A27: 273 | G27: 여 | H27: 김조은 | I27: 27 | J27: 166 | K27: 치과 | L27: 28~31 | M27: 175~ | N27: esfp | O27: 무관 | P27: 무교 | Q27: 무관 | R27: 무관 | S27: 밝고 웃음이많은 긍정적인사람이에요! 밀당을 잘 못하고 마음이 맞다는게 확인되는 순간 직진합니다. 외로움을 잘 타지 않는 스타일이고 상대를 잘 배려하려고 노력하기도합니다. | T27: 남자답고 듬직한사람을 좋아합니다. 외적으로는 마른체형을 가지고계신분은 피하는거같아요! 밝고 유쾌하신분 선호하는거 같습니다:) | U27: 0
A28: 38 | G28: 여 | H28: 김세정 | I28: 27 | J28: 160 | K28: 행사기획자(국제회의) | L28: 28~34 | M28: 175~180 | N28: ISFJ | O28: INFJ, ENFP, ESFJ | P28: 무교 | Q28: 동일 | R28: 무관 | S28: 차분하지만 밝은 사람 | T28: 유머코드, 대화가 잘 통하는 사람, 외모(두부상) | U28: 0
A29: 192 | G29: 여 | H29: 최아현 | I29: 27 | J29: 165 | K29: 대학원생 | L29: 28~34 | M29: 175~ | N29: ESFP | O29: 무관, ISTP, ISTJ, ISFJ, ESTJ | P29: 무교 | Q29: 무관 | R29: 무관 | S29: 밝고 똑부러짐 | T29: 배려심있고 자기관리 하시는 분 | U29: 0
A30: 34 | G30: 여 | H30: 김성연 | I30: 27 | J30: 169 | K30: 광고대행사 마케팅 | L30: 28~34 | M30: 170~ | N30: ESFP | O30: 무관 | P30: 무교 | Q30: 무관 | R30: 무관 | S30: 챙겨주고 챙김받는 거 좋아하는 사람 온전히 집중할 줄 아는사람 밝고 활동적인사람 | T30: 술 많이 좋아하지않고 거짓말하지않는 사람 자기일 잘 하고있고 자격지심없는사람 | U30: 0
A31: 366 | G31: 여 | H31: 임세현 | I31: 27 | J31: 162 | K31: 골든듀에이엠씨 상품관리 | L31: 28~31 | M31: 175~ | N31: ISTP | O31: 무관 | P31: 무교 | Q31: 무관 | R31: 무관 | S31: 첫인상은 조금 조용하다고 느낄수 있으나 친해지면 말도 많고 장난도 많은 편입니다 보통 주말엔 카페가서 여유로운 하루를 보내거나 집에서 OTT 보면서 시간을 보내는 편이예요 사람 만나는 것도 좋아해서 종종 친구들 만나서 수다떨고 놀기도 해요 | T31: 대화하는 걸 좋아해서 티키타카가 잘되는 사람에게 호감을 느끼는 편인 것 같아요 성격은 차분하고 따뜻한 감성적인 성격을 가진 분이 좋아요 | U31: 0
A32: 391 | C32: 1 | G32: 남 | H32: 이원준 | I32: 27 | J32: 180 | K32: 약국(사무직) | L32: 24~31 | M32: 160~165 | N32: INFP | O32: 무관 | P32: 무교 | Q32: 무관 | R32: 무관 | S32: 성실하고 다정한 사람 | T32: 강아지상에 손 예쁘고 쌍커풀 있는 사람 | U32: 0
A33: 286 | G33: 남 | H33: 심국용 | I33: 28 | J33: 187 | K33: SK텔레콤 마케팅 | L33: 20~34 | M33: 165~180 | N33: ESTJ | O33: 무관 | P33: 무교 | Q33: 무관 | R33: 무관 | S33: 다정한. 여유로운. 계획적인. | T33: 0 | U33: 0
A34: 326 | G34: 남 | H34: 정현우 | I34: 28 | J34: 171 | K34: 바리스타 | L34: 28~31 | M34: 160~170 | N34: ISTPT | O34: 무관 | P34: 무교 | Q34: 무관 | R34: 무관 | S34: 친해지면 말많고 장난 많은 사람이지만 진지할땐 진지하고 의지할수 있는 사람 | T34: 0 | U34: 초청
A35: 19 | G35: 남 | H35: 김광민 | I35: 28 | J35: 181 | K35: 회사원(플랫폼업체 영업직) | L35: 28~31 | M35: 160~170 | N35: ISFJ | O35: 무관 | P35: 무교 | Q35: 무관 | R35: 무관 | S35: 상대방에게 웃음을 주는 게 좋고 일상 대화를 하면서 평일에 받았던 스트레스가 풀리기도 합니다 처음에는 어색해하기도 하고 낯도 많이 가리기도 하지만 몇 번 얘기하다 보면 어색함도 풀리고 더 말을 걸고 있기도 합니다 일과 생활이 완벽하게 분리가 되어있어 일할 때는 일만 하고 쉴 때는 절대 일 생각도 안 하고 일 얘기도 안 하고 살아가고 있습니다 취미는 야구를 보러 다니고 주말 아침에 축구를 하러 나가고 있습니다 야구를 같이 보러 다니는 걸 좋아하며 맛있는 음식점이 생각나면 찾아가는것도 좋아합니다 집 데이트와 밖에서 하는 데이트를 한쪽으로 몰리지 않게 하는 걸 좋아합니다 연애 스타일은 주도적인 편은 아닌 거 같고 상대방에게 맞춰주는 편입니다 뭘 하든 대화를 통해 하려고 하며 싸우더라도 대화로 바로 푸는 스타일이며 한번 좋아하기 시작하면 정말 정말 많이 좋아하는 타입입니다 | T35: 안정적이며 대화가 잘 통하는 사람 연상이면 더 좋을거같고 연하는 선호하지 않습니다 | U35: 0
A36: 71 | G36: 남 | H36: 문채영 | I36: 28 | J36: 179 | K36: 모의해커 | L36: 20~27 | M36: ~175 | N36: Isfp | O36: 무관 | P36: 무교 | Q36: 동일 | R36: 0 | S36: 다정하고 알고보면 재밌는 사람?? | T36: 하얗고 고양이상에 꾸미는걸 좋아하는분 | U36: 비흡연자가 좋습니다
A37: 372 | B37: 1 | D37: 1 | G37: 여 | H37: 케리스/하은 | I37: 28 | J37: 174 | K37: 영어 강사 | L37: 28~38 | M37: 175~ | N37: INFJ | O37: 무관 | P37: 무교 | Q37: 무관 | R37: 무관 | S37: 저는 친절하고 솔직한 사람이에요. 요리하고 베이킹하는 걸 좋아해요. 다른 사람들을 행복하게 해주는 걸 좋아하고, 제가 사랑하는 사람들을 위해서라면 뭐든지 다 해요. | T37: 새로운 걸 시도하는 걸 좋아하는 사람이 좋아요. 운동하고 여행하는 것도 좋아했으면 좋겠어요. 배려심 있고 친절하고, 매너가 좋은 사람이면 더 좋아요. | U37: 초청 (5월 10일 15시)
A38: 219 | B38: 1 | G38: 여 | H38: 김세연 | I38: 28 | J38: 171.8 | K38: 분당서울대학교병원 연구간호사 | L38: 28~34 | M38: 175~ | N38: Infj | O38: INFJ, INTJ, ISFJ, ENFJ, ESFJ, ENTP, ENTJ | P38: 기독교 | Q38: 무관 | R38: 병원직군, 자영업 | S38: 낯가림이 있어 사람을 천천히 알아가는 편입니다. 여행을 통해 새로운 음식과 문화를 경험하는 것을 좋아합니다. 또한, 마음에 드는 영화나 책은 여러 번 반복해서 보는 취미가 있습니다. | T38: 마음이 따뜻하고 배려심 있는 분을 선호합니다. 제가 키가 큰 편이라, 저보다 체격이 크고 듬직한 분에게 편안함을 느끼는 것 같습니다. | U38: 0
A39: 220 | B39: 1 | G39: 여 | H39: 서동연 | I39: 28 | J39: 168 | K39: 삼성서울병원 병리과 | L39: 24~34 | M39: 170~ | N39: ISFJ | O39: 무관 | P39: 무교 | Q39: 무관 | R39: 무관 | S39: 처음엔 좀 낯을 가리긴 하는데 금방 또 잘 어울리기도 하고 내 사람이다 싶으면 한 없이 퍼주는 성격입니다! 진중한 면이 있으면서도 장난끼많아서 같이 있으면 편하고 속얘기를 다 털어놓게 되는 사람인 것 같아요 | T39: 유머코드가 잘 맞고 제가 걱정이 좀 많은 편이라 상대방은 기복이 심하지 않고 무던한 성격이 좋아요! | U39: 같은과(병리과)는 안겹치게 해주세요 !!!
A40: 221 | B40: 1 | G40: 여 | H40: 김수민 | I40: 28 | J40: 169 | K40: CRA (Clinical Research Associate, 신약개발 임상운영본부, CRO) | L40: 28~38 | M40: 175~ | N40: ESTP | O40: ISFP, INTP, ISTP, ISTJ, INTJ, ISFJ, ESFP, ESFJ, ENTP, ESTP, ENTJ, ESTJ | P40: 무교, 천주교 | Q40: 무관 | R40: 자영업, 공무원 | S40: 밝고 솔직한 성격입니당 | T40: 다정하고 대화할 때 재밌는 사람이었으면 좋겠어요. 하얗고 I인 수줍음 많은 남자 | U40: 0
...

Sheet 인기인 정렬
A1: No. | B1: 상시 | C1: 10일M | D1: 10일A | E1: 16일M | F1: 16일A | G1: 성별 | H1: 이름 | I1: 나이 | J1: 키 | K1: 직업(직장과 파트) | L1: 선호나이 | M1: 선호 키 | N1: MBTI | O1: 선호 MBTI | P1: 종교 | Q1: 상대 - 선호종교 | R1: 비선호 직군 | S1: 간단한 자기소개 | T1: 이상형 | U1: 건의사항
A2: 381 | D2: 1 | G2: 여 | H2: 김지연 | I2: 20 | J2: 155 | K2: 대학생 | L2: 20~27 | M2: 170~ | N2: Istp | O2: 무관 | P2: 무교 | Q2: 무관 | R2: 무관 | S2: 처음엔 어색해서 말도 잘 못걸고 뚝딱거리긴 하지만 조금씩 편해지면 말 많아져요!! | T2: 스스로를 잘 어울리게 꾸밀줄 아는 사람 | U2: 0
A3: 63 | G3: 여 | H3: 윤예은 | I3: 23 | J3: 168 | K3: 댄서 | L3: 24~27 | M3: 175~ | N3: ENFP | O3: INFP, INFJ, ENFP, ESFP, ENFJ | P3: 무교, 기독교 | Q3: 동일 | R3: 무관 | S3: 웃음이 많고 밝으면서 매너있고 긍정적인 사람입니다! | T3: 키가 크시고 다정한 성격이랑 말투를 가지신 분을 좋아하고 강아지상에 비흡연자이신분을 좋아합니다! | U3: 이상형에 부합하는 분이 나오셨으면 하는 바람이 있습니다:) ,,!! | V3: 키 크고 얘기가 잘 통하며 예의바르고 다정다감한 사람 | W3: 0
A4: 37 | G4: 남 | H4: 김응혁 | I4: 26 | J4: 175 | K4: 향수매장 직원 | L4: 24~31 | M4: ~165 | N4: ISTJ | O4: 무관 | P4: 무교 | Q4: 무관 | R4: 병원직군 | S4: 솔직한 사람 | T4: 기댈수있는 사람 | U4: 잘부탁드립니다! | V4: 제가 차분한 편이라, 밝고 에너제틱한 기운을 가진 분과 함께할 때 즐거움을 느낍니다. 겉모습을 화려하게 포장하기보다 자신의 있는 그대로를 사랑할 줄 아는 분이 이상형이에요. | W4: 0
A5: 43 | G5: 여 | H5: 최윤지 | I5: 27 | J5: 165 | K5: CJ_무대감독 | L5: 24~34 | M5: 175~ | N5: ESTP | O5: ISFP, ESFP, ESFJ | P5: 무교 | Q5: 동일 | R5: 자영업 | S5: 긍정적인 에너지를 가진 사람 술, 담배 안하고 타투 X /운동 헬스 필라테스 병행 중 회사 경력 5년차, 한 곳에 꾸준히 일할 수 있는 인내심 보유 T긴 하지만 애교 많고 리액션 잘하는 다정한 타입이에요 사람들과 대화하고 소통하는 일을 하고 있어서 처음봐도 어색함 없이 대하는 걸 잘해요 어딜가도 적응력이 좋아요 츄 닮았다고 자주 들어요..^,,^ 하하 | T5: 감자상 공룡상, 술,담배,타투 X 운동하고 근육덩치가 있으신 분, 말 예쁘게 하는 사람, 건실한 사람 | U5: 안녕하세요 운영진님 직업에서 직업군인은 피하고 싶어요..! 제가 직업이 방송쪽이라 교대근무여서 교대근무가 괜찮으신 분이면 좋겠습니다 좋은 사람으로 잘부탁드립니다~! 감사해요🩶 | V5: 다정하고 섬세하고 집돌이에 헬스가 취미인 사람, 흡연x | W5: 너무 나이차이가 많이나지 않았으면 좋겠어요
A6: 50 | G6: 여 | H6: 이지현 | I6: 27 | J6: 164 | K6: 보건직 | L6: 28~34 | M6: 175~ | N6: ESFJ | O6: ENTJ제외 | P6: 무교 | Q6: 동일 | R6: 병원직군, 자영업 | S6: 상대에게 잘 맞춰줄 수 있고, 활발하고 다양한 경험을 하는걸 좋아합니다. 스키, 수영, 등산 | T6: 다정다감, 성숙한, 회피형 싫고, 예의바른, | V6: 마음이 따뜻하고 배려심 있는 분을 선호합니다. 제가 키가 큰 편이라, 저보다 체격이 크고 듬직한 분에게 편안함을 느끼는 것 같습니다. | W6: 0
A7: 48 | G7: 남 | H7: 이정현 | I7: 27 | J7: 183 | K7: 삼성서울병원/ 보안팀 | L7: 20~31 | M7: ~175 | N7: ISTJ | O7: 무관 | P7: 기독교 | Q7: 무관 | R7: 무관 | S7: 평소엔 조용하지만 편해지면 생각보다 수다스럽고 장난기도 많아요. 꾸준히 운동하면서 스스로를 관리하려고 노력 중입니다. 사람 사이에서는 예의와 배려를 가장 중요하게 생각합니다. | T7: 외적으로는 반묶음 잘 어울리시는 귀여운 사람. 내적으로는 대화 잘 통하고 예의있는 사람! | U7: 이번달이 어려우면 다음달도 한 번 참여해보고싶습니다. | V7: 대화가 편하고, 같이 있을 때 웃음 포인트가 맞는 분을 좋아합니다. | W7: 0
A8: 33 | G8: 여 | H8: 박지희 | I8: 27 | J8: 165 | K8: 삼성서울병원 간호사 | L8: 24~34 | M8: 175~180 | N8: ESFJ | O8: ISFP, ISFJ, ESFP, ESFJ, ESTP | P8: 0 | Q8: 무교 | R8: 무관 | S8: 굉장히 밝고, 에너자이틱하다🤗 투명하고 감정에 솔직한 편이며, 눈치가 빨라 상대에게 잘 맞춰주는 편이다 | T8: 다정하고 배려할 줄 아는 사람, 남자다우면서 가끔은 감성도 즐겨줄 수 있는 사람 | U8: 두번째 신청입니다! 두바이 쫀득 쿠키 꼬옥 만들고 싶어요 ..🥹🩷 | V8: 스타일 좋은 사람 센스 있는 사람 | W8: 초대 감사합니다 ☺️
A9: 12 | G9: 여 | H9: 김지수 | I9: 27 | J9: 171 | K9: 삼성서울병원 암6동 | L9: 25~35 | M9: 175~185 | N9: INFJ | O9: ISTJ, ISFJ, ENFJ, ESTJ | P9: 무교 | Q9: 무관 | R9: 기술직, 자영업,공무원 | S9: 삼성서울병원 3년차 간호사 입니다. 베이킹은 처음이지만 디져트 먹는걸 참 좋아합니다~! | V9: 다정한 사람 | W9: 0
A10: 7 | G10: 남 | H10: 권오성 | I10: 27 | J10: 178 | K10: 사무직 | L10: 25~30 | M10: ~165 | N10: ESTJ | O10: INFJ, INFP, ISTJ, ISTP, ISFJ, ISFP, ENTJ, ENTP, ENFJ, ENFP, ESTP, ESFJ, ESFP | P10: 없음 | Q10: 무관 | R10: 무관 | S10: 남자입니다. 친화력이 좋은 편입니다. | V10: 밝은사람 | W10: 0
A11: 47 | G11: 여 | H11: 한민희 | I11: 28 | J11: 162 | K11: 한의원 원무직원 | L11: 28~34 | M11: 170~ | N11: ESFJ | O11: 무관 | P11: 무교 | Q11: 무관 | R11: 무관 | S11: 자가관리 잘하려고 노력하며 긍정적인 운 좋은 사람 | T11: 웃는거 이쁜 사람 청결한 사람 예의있는 사람 배울점 많은 사람 | U11: 0 | V11: 키가 크시고 다정한 성격이랑 말투를 가지신 분을 좋아하고 강아지상에 비흡연자이신분을 좋아합니다! | W11: 이상형에 부합하는 분이 나오셨으면 하는 바람이 있습니다:) ,,!!
A12: 372 | B12: 1 | D12: 1 | G12: 여 | H12: 케리스/하은 | I12: 28 | J12: 174 | K12: 영어 강사 | L12: 28~38 | M12: 175~ | N12: INFJ | O12: 무관 | P12: 무교 | Q12: 무관 | R12: 무관 | S12: 저는 친절하고 솔직한 사람이에요. 요리하고 베이킹하는 걸 좋아해요. 다른 사람들을 행복하게 해주는 걸 좋아하고, 제가 사랑하는 사람들을 위해서라면 뭐든지 다 해요. | T12: 새로운 걸 시도하는 걸 좋아하는 사람이 좋아요. 운동하고 여행하는 것도 좋아했으면 좋겠어요. 배려심 있고 친절하고, 매너가 좋은 사람이면 더 좋아요. | U12: 초청 (5월 10일 15시)
A13: 32 | G13: 남 | H13: 최봄 | I13: 28 | J13: 175 | K13: 영상의학과 방사선사 | L13: 20~31 | M13: 무관 | N13: INFJ | O13: 무관 | Q13: 0 | R13: 무관 | S13: 함께하며 대화하는 티키타카를 좋아하는 사람 | T13: 0 | U13: 선호 하는 20대 연령대분이면 좋겠습니다 | V13: 솔직하고 반전있는 스타일 | W13: 0
A14: 49 | G14: 여 | H14: 천현정 | I14: 28 | J14: 163 | K14: 간호사 | L14: 28~31 | M14: 175~ | N14: ESFJ | O14: 무관, INFJ, ISFJ, ENFJ, ESFJ | P14: 무교 | Q14: 동일 | R14: 자영업, 공무원 | S14: 밝고 사람과 함께하는걸 좋아하는 사람입니다. 자기관리 잘하며 프리패스 며느리상.. | T14: 자기관리 하는사람, 성실한 사람, 훈훈한 외모 | U14: 작년부터 병동 선생님들의 추천으로 하고싶었는데 듀티가 나오지 않아 지원하지 못했습니다. 이번 기회에 참여해보고 싶습니다ㅎㅎ | V14: 책임감있고 다정한 사람 감정표현 잘하는 사람 | W14: 0
A15: 20 | E15: 1 | F15: 1 | G15: 여 | H15: 이현주 | I15: 28 | J15: 165 | K15: 서울시 공무원 | L15: 25~35 | M15: 175~185 | N15: intp | O15: 무관 | P15: 무교 | Q15: 무관 | R15: 자영업, 공무원 | S15: 안녕하세요! 잘 부탁드립니다 | T15: 모든 것에서 좋은 점을 찾을 수 있다 ! | V15: 깔끔한 인상에 자기관리 잘하고 웃는게 이쁜 사람. 운동 꾸준히 하고 피부를 잘 가꾸는 사람. | W15: 0
A16: 4 | G16: 남 | H16: 왕인상 | I16: 28 | J16: 178 | K16: 외국계 에스테틱회사(세일즈 교육팀) | L16: 25~30 | M16: ~165 | N16: ESFP | O16: ISTJ, ISFJ, ENTJ, ENFJ, ESTJ, ESFJ | P16: 무교 | Q16: 무관 | R16: 무관 | S16: 안녕하세요~~~!!! 지인의 공고 전달을 받고 참여를 안할래야 안할수가 없어 지원했습니다~~! | V16: 서로를 위한 존경과 내조 | W16: 0
A17: 58 | G17: 남 | H17: 심국용 | I17: 28 | J17: 187 | K17: SK텔레콤 마케팅 | L17: 20~34 | M17: 165~180 | N17: ESTJ | O17: 무관 | P17: 무교 | Q17: 무관 | R17: 무관 | S17: 다정한. 여유로운. 계획적인. | T17: 0 | U17: 0 | V17: 0 | W17: 0
A18: 54 | G18: 남 | H18: 손기범 | I18: 28 | J18: 168 | K18: 인스파이어 카지노딜러 | L18: 20~30 | M18: 165~170 | N18: ENFP | O18: 무관 | P18: 무교 | Q18: 무관 | R18: 무관 | S18: 카지노딜러하고있는 27살 손기범입니다 | T18: 작고 아담하신분, 지혜로운 | U18: 0 | V18: 외적, 작고 아담한 스타일 (연예인, 박보영 남보라 윈터) 내적, 든든한 동료로서 미래를 함께 그려나갈 수 있는 분 | W18: 베이킹을 통해 인연을 만나는 자리가 있다는걸 처음 알았네요, 좋은 자리 만들어주셔서 감사합니다. 좋은 인연 만날 수 있기를 기원합니다🙏
A19: 31 | G19: 여 | H19: 박혜연 | I19: 28 | J19: 162 | K19: 간호사(건진내시경) | L19: 28~34 | M19: 175~180 | N19: INTP | O19: 무관 | R19: 병원직군, 연구직 | S19: 안녕하세요 삼성서울병원 건진내시경실 간호사로 일하고있는 박혜연 입니다. 복싱 | T19: 예의바른 사람 | V19: 외적인건 코가 예쁘고 눈이 날카롭지 않은 사람이 좋은 것 같아요. 내적으로는 똑똑하고 지혜롭고 감정기복 없고 성실한 사람이 좋습니다. 잘 웃는 사람도 좋아요! | W19: 0
A20: 13 | G20: 여 | H20: 김채희 | I20: 28 | J20: 168 | K20: 삼성서울병원 외래지원파트 | L20: 25~35 | M20: 175~ | N20: ISFJ | O20: ISFJ, ENTJ, ENFJ, ESTJ, ESTP, ESFJ, ESFP | P20: 무교 | Q20: 무관 | R20: 무관 | S20: 안녕하세요. 저는 28살 5년차 간호사 김채희 입니다!:) | V20: 다정하고 대화할 때 재밌는 사람이었으면 좋겠어요. 하얗고 I인 수줍음 많은 남자 | W20: 0
A21: 57 | G21: 남 | H21: 김광민 | I21: 28 | J21: 181 | K21: 회사원(플랫폼업체 영업직) | L21: 28~31 | M21: 160~170 | N21: ISFJ | O21: 무관 | P21: 무교 | Q21: 무관 | R21: 무관 | S21: 상대방에게 웃음을 주는 게 좋고 일상 대화를 하면서 평일에 받았던 스트레스가 풀리기도 합니다 처음에는 어색해하기도 하고 낯도 많이 가리기도 하지만 몇 번 얘기하다 보면 어색함도 풀리고 더 말을 걸고 있기도 합니다 일과 생활이 완벽하게 분리가 되어있어 일할 때는 일만 하고 쉴 때는 절대 일 생각도 안 하고 일 얘기도 안 하고 살아가고 있습니다 취미는 야구를 보러 다니고 주말 아침에 축구를 하러 나가고 있습니다 야구를 같이 보러 다니는 걸 좋아하며 맛있는 음식점이 생각나면 찾아가는것도 좋아합니다 집 데이트와 밖에서 하는 데이트를 한쪽으로 몰리지 않게 하는 걸 좋아합니다 연애 스타일은 주도적인 편은 아닌 거 같고 상대방에게 맞춰주는 편입니다 뭘 하든 대화를 통해 하려고 하며 싸우더라도 대화로 바로 푸는 스타일이며 한번 좋아하기 시작하면 정말 정말 많이 좋아하는 타입입니다 | T21: 안정적이며 대화가 잘 통하는 사람 연상이면 더 좋을거같고 연하는 선호하지 않습니다 | U21: 0 | V21: 관계 유지에 노력을 기울이는 사람을 선호합니다. 외적으로는 작고 귀여운 두부상 스타일 좋아합니다. | W21: 0
A22: 64 | G22: 여 | H22: 고도연 | I22: 28 | J22: 158 | K22: 삼성서울병원, 신생아중환자실 간호사 | L22: 25~35 | M22: 175~185 | N22: Istp | O22: INTJ, INTP, INFJ, ISTJ, ISTP, ISFJ, ISFP, ENTJ, ENTP, ENFJ, ESTJ, ESTP, ESFJ, ESFP | P22: 무교 | Q22: 동일 | R22: 0 | S22: 안녕하세요! 저는 올해로 4년차 직장인이 된 고도연입니다. 베이킹에 관심은 많지만 1인 가구의 특성상 빵을 만들기는 어려운 현실입니다•• 매번 눈여겨 보고 있던 케미스트리 오븐을 통해 사람들과 두쫀쿠를 만들며 1월 행복하게 마무리 해보고 싶습니다 ☺️ •• 겉으로는 바삭 딱딱해보이지만 속은 부드럽(?)답니다. 긍정적이고 웃음이 많고 여러 사람과 어울리는 것을 잘합니다 :) | T22: 0 | U22: 0 | V22: 따뜻, 섬세, 안정형 | W22: 0
A23: 14 | G23: 여 | H23: 윤수선 | I23: 29 | J23: 163 | K23: 간호사 ( 가천대 길병원, 마취과) | L23: 30~35 | M23: 170~ | N23: ESFJ | O23: INTJ, INTP, INFJ, INFP, ISTJ, ISFP | P23: 무교 | Q23: 무관 | R23: 자영업, 공무원 | S23: 안녕하세요! 소개팅은 어렵고 자연스러운 만남을 통해 매력을 어필하여 저와 대화가 잘통하는 인연을 이번 좋은 기회를 통해 만나고싶습니다. 여러번 보아야 매력을 보일 수 있는 저에게 좋을 것 같아 신청했습니다 서로의 장점을 보고 좋은 인연 만들어서 나가고 싶어요 인연이 되지않아도 배이킹을 즐기고 갈 자신 있습니다!! 새로운걸 도전하는걸 좋아하기 때문입니다 긍정적인 파워를 보여드리겠습니다 ! | V23: 다정한사람 | W23: 0
A24: 30 | G24: 여 | H24: 박지혜 | I24: 29 | J24: 158 | K24: 삼성서울병원(간호사) | L24: 30~35 | M24: 175~185 | N24: Isfp | O24: 무관 | R24: 무관 | S24: 안녕하세요 얼마전 이별해서 참가신청했습니다ㅎㅎ | T24: 잘 주차된 이목구비 | V24: 웃는모습이예쁜남자 | W24: 0
A25: 17 | G25: 여 | H25: 박유임 | I25: 29 | J25: 165 | K25: 간호사 삼성서울병원 | L25: 25~35 | M25: 180~185 | N25: ENFP | O25: 무관 | P25: 무교 | Q25: 본인과 동일 | R25: 병원직군 | S25: 여행을 좋아하고 맛집탐방 좋아합니다 !, 차분하면서 활동적인 느낌 웃음이 많다 ! | V25: 외적인건 하얀사람을 좋아하고 같이있을때 편하고 재밌는사람이 좋습니다. | W25: 0
A26: 65 | G26: 여 | H26: 김어진 | I26: 29 | J26: 158 | K26: 삼성서울병원 외래간호 | L26: 25~40 | M26: 170~ | N26: INFP | O26: 무관 | P26: 무관 | Q26: 무교 | R26: 무관 | S26: 안녕하세요 삼성서울병원 외래간호팀에서 근무하는 김어진입니다./ 성격이 좋습니다. 피부가 하얗고 좋아요 | T26: 0 | U26: 0 | V26: 활발한사람 | W26: 감사합니다. !
A27: 38 | G27: 남 | H27: 김성중 | I27: 29 | J27: 175 | K27: 서울도시가스 (기술직) | L27: 24~27 | M27: ~165 | N27: ESTJ | O27: 무관 | P27: 무교 | Q27: 무관 | R27: 무관 | S27: 현실적이고 이상적이며 열심히 살고있는 개미에요 | T27: 애교 많고 청순한 스타일 | U27: 0 | V27: 잘웃고, 잘먹고, 잘놀고, 본인업무에 성취감을 느끼는 사람 | W27: 요즘엔 버터떡이 유행이더라구요?!? 뭐든 좋긴해요!
A28: 69 | G28: 여 | H28: 김길원 | I28: 29 | J28: 161 | K28: 삼성서울병원 중환자실 | L28: 28~34 | M28: 170~ | N28: ENFP | O28: INTJ, ENTJ | P28: 무교 | Q28: 무관 | R28: 무관 | S28: 제 가장 큰 장점은 유연함입니다. 또 세상에 호기심이 많고 긍정적인 편입니다. 그래서 주변과 잘 어울립니다. 저는 글보다 직접 보는게 더 나은 사람이라고 생각해요. 잘 부탁드립니다 ㅎㅎ | T28: 어느정도 자기관리 되어 있는 똑 부러지는 사람. 책임감있는 사람. Entj Intj 극극선호합니다. | U28: 잘 부탁드립니다. 저번에 참여하지 못했는데 이번에는 기회주시면 책임감 가지고 꼭 참여하겠습니다. | V28: 밝고 긍정적이고 잘 웃으시는 분 | W28: 잘부탁드립니다 😊
A29: 60 | G29: 남 | H29: 강희문 | I29: 29 | J29: 177 | K29: 차량손해사정사 | L29: 24~31 | M29: 160~165 | N29: ISTP | O29: 무관 | P29: 무교 | Q29: 무관 | R29: 무관 | S29: 감정 변화가 크지 않고 내 사람한테 다정함 | T29: 단발 | U29: 0 | V29: 감자상 공룡상, 술,담배,타투 X 운동하고 근육덩치가 있으신 분, 말 예쁘게 하는 사람, 건실한 사람 | W29: 안녕하세요 운영진님 직업에서 직업군인은 피하고 싶어요..! 제가 직업이 방송쪽이라 교대근무여서 교대근무가 괜찮으신 분이면 좋겠습니다 좋은 사람으로 잘부탁드립니다~! 감사해요🩶
A30: 26 | G30: 여 | H30: 허진영 | I30: 30 | J30: 159 | K30: SMC 간호사 5서병동 | L30: 28~ | M30: 175~ | N30: ESTP | O30: INTJ, INTP, INFJ, ISTJ, ISTP, ISFJ, ENTJ, ENTP, ENFJ, ENFP, ESTJ, ESTP, ESFJ, ESFP | R30: 병원직군, 기술직, 자영업, 공무원, 연구직, 회사원, 무관 | S30: 반갑습니다 정말 잘해보고 싶어요~ | T30: 긍정적이고 선입견이 없습니다 | V30: 말 이쁘게 하시는분. | W30: 0
A31: 70 | G31: 남 | H31: 정재우 | I31: 30 | J31: 182 | K31: 건국대학교 교직원 | L31: 24~34 | M31: ~175 | N31: ENFP | O31: 무관 | P31: 천주교 | Q31: 무관 | R31: 무관 | S31: 안녕하세요 내향적이지만 내사람한테는 재미있고 유머있는 밝은 성격입니다. 좋은 분과 맛있는 베이킹 하고싶어 나왔습니다. 잘 부탁드립니다. | T31: 이야기를 같이 나누고 친해질수록 더 재미있고 매력을 많이 확인할 수 있습니다. | V31: 상대방을 존중해주는 사람 | W31: 0
A32: 23 | G32: 남 | H32: 전성준 | I32: 30 | J32: 172 | K32: 삼성서울병원 혈액종양내과 간호사 | L32: 25~30 | M32: 160~165 | N32: ISFJ | O32: INFJ, INFP, ISFJ, ISFP, ENFJ, ENFP, ESFJ, ESFP | P32: 병원직군 | Q32: 불교 | R32: 동일 | S32: 환자 보호자들에게 인기많은 칭찬간호사입니다.운동좋아하고 한결같은 성격 | T32: 0 | U32: 0 | V32: 밝고 긍정적인 사람 | W32: 0
A33: 59 | G33: 남 | H33: 이준호 | I33: 30 | J33: 184 | K33: 연구소, 연구원 | L33: 24~31 | M33: 160~180 | N33: ENFJ | O33: 무관, INFP, ISFP | P33: 천주교 | Q33: 무관 | R33: 무관 | S33: 낭만적인것 좋아고 배우는 활동에 진심인 사람 | T33: 회피하지 않고 해결하고자하는 자세가 먼저 인 사람, 여유러운 일상생활을 즐길 수 있는 분 | U33: 0 | V33: 0 | W33: 0
A34: 8 | G34: 남 | H34: 박영진 | I34: 30 | J34: 180 | K34: 삼성서울병원 수술실 간호사 | L34: 20~30 | M34: ~170 | N34: ISFJ | O34: INFJ, ISFJ, ISFP, ENFP, ESFJ | P34: 무교 | Q34: 동일 | R34: 자영업 | V34: 잘 웃고 밝은 에너지를 가진 분에게 자연스럽게 끌립니다. 외적으로는 고양이상이나 여우상처럼 분위기가 또렷한 분을 선호하고, 웃을 때 매력이 느껴지는 분에게 호감을 느끼는 편입니다. | W34: 0
A35: 66 | G35: 여 | H35: 김지운 | I35: 30 | J35: 156 | K35: 의료직 | L35: 28~31 | M35: 175~180 | N35: INFP or INTP | O35: 무관 | P35: 무교 | Q35: 무관 | R35: 무관 | S35: 착하고 리액션 잘함, 장난도 적당히 선 안 넘게 치고 티키타카 웬만하면 잘 됨 | T35: 빠른 눈치와 기본 도덕성과 인성이 있는 사람, 외적으로는 적당히 자기관리 하고 눈이 작지 않고 피부 깨끗한 사람 | U35: 저 다른 어플에서 사진으로 많이 속아서 현타왔어요... 살려주세요..... | V35: 도전적이고, 자기 할 일에 열정적인 사람 / 나한테만 다정한 사람 | W35: 0
A36: 39 | G36: 여 | H36: 조수진 | I36: 31 | J36: 155 | K36: 교사(중학교) | L36: 28~34 | M36: 170~ | N36: ENFJ | O36: 무관 | P36: 무교 | Q36: 동일 | R36: 무관 | S36: 밝고 긍정적이고 일에도 열정이 가득한 사람. 사람을 좋아하고 웃음이 많음. 책임감이 강하고 남을 배려하는 사람. 거절을 잘 못 함. 책과 음악을 좋아하고 영화나 드라마도 좋아함. 운명적인 사랑을 믿고 운명을 기다리는 사람. 상처도 잘 받지만 또 금새 털어버리는 사람(잘 까먹음). 동물을 사랑하고 세상에 긍정적인 영향력을 조금이라도 미치고 싶은 사람. 바르게 살기 위해 노력하는 사람. 같이 있는 사람(친구나 연인)에게 동화가 잘 되는 편. | T36: 듬직하고 다정한 사람. 성격이 선하고 바른 사람. 담배를 피지 않고, 운동을 좋아하는 사람. 대화가 잘 통하고 편안하면서도 같이 있는게 너무 즐거운 사람. 웃음 코드가 잘 맞고, 다른 사람에게 상처주는 말이나 행동을 웃음 소재로 쓰지 않는 사람. 기본적인 예의가 있는 사람. 자기 일에 열정적인 사람. 내면이 단단하고 말을 예쁘게 하는 사람. | U36: 직업 무관이라고 했지만 교사는 아니었으면 좋겠습니다. 운명을 만나면 좋겠지만 아니더라도 베이킹이 너무 기대됩니다! | V36: 말이쁘게 하는 사람 | W36: 없습니다
A37: 18 | G37: 여 | H37: 임채영 | I37: 31 | J37: 169 | K37: 삼성서울병원 영상의학과(의사) | L37: 25~35 | M37: 165~ | N37: INTP | O37: 무관 | P37: 천주교 | Q37: 본인과 동일 | R37: 무관 | S37: 안녕하세요 호기심과 웃음이 많은 임채영입니다 가종이 화목합니다 | V37: #다정함 #긍정적 #정돈됨 #주관있는 | W37: 0
A38: 24 | G38: 여 | H38: 이반야 | I38: 31 | J38: 160 | K38: 서울삼성병원 | L38: 30~35 | M38: 170~185 | N38: Infp | O38: 무관 | R38: 무관 | S38: 저는 긍적적이고 리액션이 좋습니다! 귀엽게 생겨서 호감형이라고 생각합니다 ㅎㅎ | T38: 성실하고 착하다 | V38: 말이쁘게 하는 사람 | W38: 없습니다
A39: 19 | G39: 남 | H39: 양성인 | I39: 31 | J39: 177 | K39: 삼성병원 신경검사실 | L39: 25~35 | M39: 무관 | N39: ENFP | O39: 무관 | P39: 기독교 | Q39: 동일 | R39: 무관 | S39: 에겐남 양성인입니다 | T39: 활동적이고 운동을 좋아해요! | V39: 0 | W39: 0
A40: 36 | G40: 남 | H40: 김반석 | I40: 31 | J40: 176 | K40: IT엔지니어 | L40: 28~31 | M40: 160~170 | N40: ISFP | O40: 무관 | P40: 기독교 | Q40: 무관 | R40: 무관 | S40: 저는 솔직한 편이라, 좋고 싫은 게 표정에 조금 드러나는 편이에요. 그래서 오히려 편하다는 얘기를 듣기도 해요. 인연을 소중하게 생각하는 편이라 한 번 만나면 오래 보고 싶은 스타일이고요. 너무 무겁기보다는, 가끔씩 툭툭 웃기는 편이에요. 목표가 생기면 어떻게든 이루려고 노력하는 편이라, 스스로는 진취적인 성향이라고 생각합니다. 잘 부탁드립니다 🙂 | T40: 비흡연자였으면 좋겠고, 긴 머리가 잘 어울리는 분을 좋아해요. 연하이신 분이 조금 더 편하게 느껴지고, 같이 있을 때 밝고 에너지가 좋은 분이면 더 잘 맞을 것 같아요. | U40: 0 | V40: 애교 많고 청순한 스타일 | W40: 0
...

Sheet 인원선정 최종
A1: No. | B1: 상시 | C1: 10일M | D1: 10일A | E1: 16일M | F1: 16일A | G1: 성별 | H1: 이름 | I1: 나이 | J1: 키 | K1: 직업(직장과 파트) | L1: 선호나이 | M1: 선호 키 | N1: MBTI | O1: 선호 MBTI | P1: 종교 | Q1: 상대 - 선호종교 | R1: 비선호 직군 | S1: 간단한 자기소개 | T1: 이상형 | U1: 건의사항
G2: 10일 11시
A3: 26 | C3: 1 | D3: 1 | G3: 남 | H3: 신희건 | I3: 33 | J3: 174 | K3: 공무원/소방공무원 | L3: 28~34 | M3: ~165 | N3: ISTJ | O3: INFP, ISFP, INFJ, ISTJ, ISFJ, ENFP, ESFP, ENFJ, ESFJ, ENTP, ESTP, ENTJ, ESTJ | P3: 무교 | Q3: 동일 | R3: 병원직군, 공무원, 연구직, 회사원 | S3: 해보고 싶은 것이 생기면 도전해보는 사람 | T3: 웃음이 많고 성격이 밝은 사람 | U3: 0
A4: 356 | C4: 1 | G4: 남 | H4: 정재우 | I4: 30 | J4: 182 | K4: 건국대학교 교직원 | L4: 24~34 | M4: ~175 | N4: ENFP | O4: 무관 | P4: 천주교 | Q4: 무관 | R4: 이야기를 같이 나누고 친해질수록 더 재미있고 매력을 많이 확인할 수 있습니다. | S4: 무관 | T4: 안녕하세요 내향적이지만 내사람한테는 재미있고 유머있는 밝은 성격입니다. 좋은 분과 맛있는 베이킹 하고싶어 나왔습니다. 잘 부탁드립니다. | U4: 0
A5: 19 | C5: 1 | G5: 남 | H5: 김광민 | I5: 28 | J5: 181 | K5: 회사원(플랫폼업체 영업직) | L5: 28~31 | M5: 160~170 | N5: ISFJ | O5: 무관 | P5: 무교 | Q5: 무관 | R5: 무관 | S5: 상대방에게 웃음을 주는 게 좋고 일상 대화를 하면서 평일에 받았던 스트레스가 풀리기도 합니다 처음에는 어색해하기도 하고 낯도 많이 가리기도 하지만 몇 번 얘기하다 보면 어색함도 풀리고 더 말을 걸고 있기도 합니다 일과 생활이 완벽하게 분리가 되어있어 일할 때는 일만 하고 쉴 때는 절대 일 생각도 안 하고 일 얘기도 안 하고 살아가고 있습니다 취미는 야구를 보러 다니고 주말 아침에 축구를 하러 나가고 있습니다 야구를 같이 보러 다니는 걸 좋아하며 맛있는 음식점이 생각나면 찾아가는것도 좋아합니다 집 데이트와 밖에서 하는 데이트를 한쪽으로 몰리지 않게 하는 걸 좋아합니다 연애 스타일은 주도적인 편은 아닌 거 같고 상대방에게 맞춰주는 편입니다 뭘 하든 대화를 통해 하려고 하며 싸우더라도 대화로 바로 푸는 스타일이며 한번 좋아하기 시작하면 정말 정말 많이 좋아하는 타입입니다 | T5: 안정적이며 대화가 잘 통하는 사람 연상이면 더 좋을거같고 연하는 선호하지 않습니다 | U5: 0
A6: 391 | C6: 1 | G6: 남 | H6: 이원준 | I6: 27 | J6: 180 | K6: 약국(사무직) | L6: 24~31 | M6: 160~165 | N6: INFP | O6: 무관 | P6: 무교 | Q6: 무관 | R6: 무관 | S6: 성실하고 다정한 사람 | T6: 강아지상에 손 예쁘고 쌍커풀 있는 사람 | U6: 0
A7: 41 | B7: 1 | C7: 1 | G7: 여 | H7: 김수경 | I7: 26 | J7: 171 | K7: 보령 제약회사, 학술팀 | L7: 24~34 | M7: 180~ | N7: INTP, ISTP 둘다 나와요 | O7: ISTJ, INTJ, ISFJ, ESFJ, ESTP, ENTJ, ESTJ | P7: 무교 | Q7: 동일 | R7: 자영업 | S7: 처음에는 낯을 가리는데 1:1로 보면 말을 많이 하는 사람인것 같아요〰 털털한 것 같고 사람들을 웃기는 걸 좋아하는데 또 저도 잘 웃는 것 같습니다. 운동을 좋아하고 잘하는 편이에요 | T7: 외적인건 코가 예쁘고 눈이 날카롭지 않은 사람이 좋은 것 같아요. 내적으로는 똑똑하고 지혜롭고 감정기복 없고 성실한 사람이 좋습니다. 잘 웃는 사람도 좋아요! | U7: 0
A8: 305 | B8: 1 | C8: 1 | G8: 여 | H8: 박세란 | I8: 26 | J8: 164 | K8: 삼성서울병원 건강의학본부 임상병리사 | L8: 24~31 | M8: 170~ | N8: ISFJ | O8: 무관 | P8: 무교 | Q8: 동일, 무관 | R8: 자영업 | S8: 배려, 차분, 리액션 퀸 | T8: 따뜻, 섬세, 안정형 | U8: 0
